Workbook

Sheet 2-2026
A1: Line | B1: Hiring Date | C1: Code | D1: Name | E1: Area | F1: Target Customers | G1: Target Customers Visited | H1: Target Customers Visit Coverage % | I1: Not Covered Customers | J1: Visited Customers | K1: Actual Visits | L1: Visits per Customer | M1: Fully Covered Customers | N1: ECRP%
A3: Diab III | B3: 12-Jul-2025 | C3: 1707 | D3: AbdelMoneim Sayed AbdelMoneim Sayed Darwish | E3: DIAB-III ABBASEIA-KOBBAH | F3: 79 | G3: 76 | H3: 0.96202532 | I3: 3 | J3: 76 | K3: 169 | L3: 2.2236842 | M3: 63 | N3: 0.79746835
A4: Diab III | B4: 22-Jun-2024 | C4: 1188 | D4: Mahmoud Mohamed Abdelmahdy Abdullah | E4: DIAB-III CAIRO EAST | F4: 71 | G4: 66 | H4: 0.92957746 | I4: 5 | J4: 71 | K4: 161 | L4: 2.2676056 | M4: 40 | N4: 0.56338028
A5: Diab III | B5: 1-Dec-2024 | C5: 1331 | D5: Yasmin Sayed AbdelLatif Mohamed Hekal | E5: DIAB-III AIN SHAMS | F5: 72 | G5: 68 | H5: 0.94444444 | I5: 4 | J5: 68 | K5: 158 | L5: 2.3235294 | M5: 60 | N5: 0.83333333
A6: Diab III | B6: 46025 | C6: 2008 | D6: Guirgis Samir Azmy Iskandar | E6: DIAB-III HELIOPOLIS-A | F6: 74 | G6: 65 | H6: 0.87837838 | I6: 9 | J6: 74 | K6: 134 | L6: 1.8108108 | M6: 27 | N6: 0.36486486
A7: Diab III | B7: 7-Sept-2024 | C7: 1268 | D7: Mariam Makram Ragheb Soliman | E7: DIAB-III HELIOPOLIS-B | F7: 80 | G7: 77 | H7: 0.9625 | I7: 3 | J7: 77 | K7: 154 | L7: 2 | M7: 44 | N7: 0.55
A8: Diab III | D8: Vacant_NasrCity | E8: DIAB-III NASR CITY | F8: 0 | G8: 0 | H8: 0 | I8: 0 | J8: 0 | K8: 0 | L8: 0 | M8: 0 | N8: 0
A9: Diab III | B9: 1-Jan-2024 | C9: 1006 | D9: Kholoud El-Matarawy Mohamed Aly | E9: DIAB-III NEW CAIRO | F9: 78 | G9: 71 | H9: 0.91025641 | I9: 7 | J9: 73 | K9: 154 | L9: 2.109589 | M9: 48 | N9: 0.61538462
A10: Diab III | B10: 46032 | C10: 2007 | D10: Rania Helmy Lotfy Mohamed ElAsour | E10: DIAB-III ISMAILIA-SUIZ | F10: 89 | G10: 53 | H10: 0.59550562 | I10: 36 | J10: 53 | K10: 66 | L10: 1.245283 | M10: 8 | N10: 0.08988764
A11: Diab III | B11: 1-Feb-2025 | C11: 1439 | D11: Peter AbdelNasser Fathy Habel | E11: DIAB-III DM CAIRO B | F11: 380 | G11: 358 | H11: 0.94210526 | I11: 22 | J11: 365 | K11: 796 | L11: 2.1848817 | M11: 255 | N11: 0.67105263
A12: Diab III | D12: Vacant_Shoubraelkhemah | E12: DIAB-III SHOBRA EL KHEMAH | F12: 0 | G12: 0 | H12: 0 | I12: 0 | J12: 0 | K12: 0 | L12: 0 | M12: 0 | N12: 0
A13: Diab III | B13: 2-Nov-2025 | C13: 1839 | D13: Eman Hamdy Shahat Esmail | E13: DIAB-III CAIRO WEST | F13: 73 | G13: 71 | H13: 0.97260274 | I13: 2 | J13: 71 | K13: 144 | L13: 2.028169 | M13: 39 | N13: 0.53424658
A14: Diab III | B14: 46023 | C14: 2018 | D14: Mohamed Mostafa Mohamed Mahmoud Azzam | E14: DIAB-III CAIRO CENTER | F14: 74 | G14: 63 | H14: 0.85135135 | I14: 11 | J14: 63 | K14: 120 | L14: 1.9047619 | M14: 40 | N14: 0.54054054
A15: Diab III | B15: 46032 | C15: 2074 | D15: Asmaa ElBel Zanaty Hussein Aly | E15: DIAB-III CAIRO SOUTH | F15: 95 | G15: 78 | H15: 0.82105263 | I15: 17 | J15: 78 | K15: 131 | L15: 1.6794872 | M15: 24 | N15: 0.25263158
A16: Diab III | B16: 29-Aug-2020 | C16: 230 | D16: Nourhan Ashraf Mostafa Hassan | E16: DIAB-III MAADI | F16: 58 | G16: 0 | H16: 0 | I16: 58 | J16: 0 | K16: 0 | L16: 0 | M16: 0 | N16: 0
A17: Diab III | B17: 1-Jan-2024 | C17: 964 | D17: Fatma Fawzy Mohamed Mahmoud | E17: DIAB-III HELWAN | F17: 79 | G17: 69 | H17: 0.87341772 | I17: 10 | J17: 69 | K17: 127 | L17: 1.8405797 | M17: 32 | N17: 0.40506329
A18: Diab III | B18: 46033 | C18: 2075 | D18: Maha Magdy AbdelSalam Mahmoud Farag | E18: DIAB-III QALUBIA-A | F18: 77 | G18: 74 | H18: 0.96103896 | I18: 3 | J18: 75 | K18: 164 | L18: 2.1866667 | M18: 43 | N18: 0.55844156
A19: Diab III | B19: 46023 | C19: 2019 | D19: Mahmoud Lotfy Saied AbdelFatah | E19: DIAB-III QALUBIA-B | F19: 82 | G19: 76 | H19: 0.92682927 | I19: 6 | J19: 77 | K19: 147 | L19: 1.9090909 | M19: 42 | N19: 0.51219512
A20: Diab III | B20: 46023 | C20: 1902 | D20: Ahmed Adel Hosny Hassan | E20: DIAB-III DM CAIRO A | F20: 210 | G20: 140 | H20: 0.66666667 | I20: 70 | J20: 140 | K20: 271 | L20: 1.2895829 | M20: 71 | N20: 0.33809524
A21: Diab III | B21: 10-Aug-2024 | C21: 1248 | D21: Mariam AbdelRahman Abdel Samie Abdel Wadod | E21: DIAB-III SHARKIA-A | F21: 102 | G21: 93 | H21: 0.91176471 | I21: 9 | J21: 93 | K21: 163 | L21: 1.7526882 | M21: 57 | N21: 0.55882353
A22: Diab III | B22: 46023 | C22: 2020 | D22: Youssef AbdelBaset Esmail Ahmed Ammar Badran | E22: DIAB-III SHARKIA-B | F22: 95 | G22: 75 | H22: 0.78947368 | I22: 20 | J22: 83 | K22: 156 | L22: 1.8795181 | M22: 46 | N22: 0.48421053
A23: Diab III | B23: 46032 | C23: 2039 | D23: Anas Mohamed ElSayed Ibrahim Salem | E23: DIAB-III SHARKIA-C | F23: 83 | G23: 66 | H23: 0.79518072 | I23: 17 | J23: 82 | K23: 131 | L23: 1.597561 | M23: 31 | N23: 0.37349398
A24: Diab III | B24: 1-Jan-2024 | C24: 1047 | D24: Alaa Aly Aly Abu El-Enein | E24: DIAB-III DAKAHLIA-A | F24: 87 | G24: 86 | H24: 0.98850575 | I24: 1 | J24: 87 | K24: 158 | L24: 1.816092 | M24: 56 | N24: 0.64367816
A25: Diab III | B25: 14-Mar-2024 | C25: 1117 | D25: Reem Hassan Tolba Ibrahim | E25: DIAB-III DAKAHLIA-B | F25: 83 | G25: 75 | H25: 0.90361446 | I25: 8 | J25: 75 | K25: 123 | L25: 1.64 | M25: 55 | N25: 0.6626506
A26: Diab III | B26: 46023 | C26: 2021 | D26: Donia Mahmoud Mohamed Ahmed Mowafy | E26: DIAB-III DAKAHLIA-C | F26: 76 | G26: 76 | H26: 1 | I26: 0 | J26: 76 | K26: 169 | L26: 2.2236842 | M26: 69 | N26: 0.90789474
A27: Diab III | B27: 18-Jul-2020 | C27: 194 | D27: Menna Allah Hassouna Abbas Hassouna | E27: DIAB-III DOMIAT | F27: 77 | G27: 73 | H27: 0.94805195 | I27: 4 | J27: 73 | K27: 163 | L27: 2.2328767 | M27: 27 | N27: 0.35064935
A28: Diab III | B28: 1-Jan-2024 | C28: 998 | D28: Shereen Tarek Gouda El-Sayed | E28: DIAB-III P. SAID-N. SINAI | F28: 66 | G28: 61 | H28: 0.92424242 | I28: 5 | J28: 62 | K28: 150 | L28: 2.4193548 | M28: 19 | N28: 0.28787879
A29: Diab III | D29: Vacant_Delta 1 | E29: DIAB-III DM DELTA A | F29: 415 | G29: 388 | H29: 0.93493976 | I29: 27 | J29: 390 | K29: 757 | L29: 1.9722023 | M29: 214 | N29: 0.51566265
A30: Diab III | B30: 46023 | C30: 1992 | D30: Mostafa Mahmoud Gaber ElHajjar | E30: DIAB-III MENOFYA-A | F30: 78 | G30: 68 | H30: 0.87179487 | I30: 10 | J30: 81 | K30: 162 | L30: 2 | M30: 38 | N30: 0.48717949
A31: Diab III | B31: 46023 | C31: 1995 | D31: Zeinab Serry AbdelSamie Ammar | E31: DIAB-III MENOFYA-B | F31: 72 | G31: 66 | H31: 0.91666667 | I31: 6 | J31: 78 | K31: 155 | L31: 1.9871795 | M31: 48 | N31: 0.66666667
A32: Diab III | B32: 46023 | C32: 1994 | D32: Mariam AbuElMagd Ibrahim Abdullah ElNaggar | E32: DIAB-III GHARBIA-B | F32: 96 | G32: 69 | H32: 0.71875 | I32: 27 | J32: 75 | K32: 139 | L32: 1.8533333 | M32: 38 | N32: 0.39583333
A33: Diab III | D33: Vacant_Gharbia_II | E33: DIAB-III GHARBIA-C | F33: 0 | G33: 0 | H33: 0 | I33: 0 | J33: 0 | K33: 0 | L33: 0 | M33: 0 | N33: 0
A34: Diab III | B34: 46023 | C34: 1993 | D34: Mohamed Ahmed ElSayed Ahmed ElTaras | E34: DIAB-III GHARBIA-A | F34: 90 | G34: 53 | H34: 0.58888889 | I34: 37 | J34: 86 | K34: 141 | L34: 1.6395349 | M34: 20 | N34: 0.22222222
A35: Diab III | B35: 46054 | C35: 2133 | D35: Hazem Mohamed HasaBallah Esmail Ibrahim | E35: DIAB-III KAFR ELSHEIKH-A | F35: 71 | G35: 31 | H35: 0.43661972 | I35: 40 | J35: 36 | K35: 40 | L35: 1.1111111 | M35: 6 | N35: 0.084507042
A36: Diab III | B36: 2-Nov-2023 | C36: 940 | D36: Mohamed Mohamed Mohamed Hassan Salah | E36: DIAB-III KAFR ELSHEIKH-B | F36: 79 | G36: 70 | H36: 0.88607595 | I36: 9 | J36: 72 | K36: 147 | L36: 2.0416667 | M36: 25 | N36: 0.3164557
A37: Diab III | B37: 44703 | C37: 576 | D37: Mohamed ElSayed Mostafa Gaber | E37: DIAB-III DM DELTA B | F37: 79 | G37: 70 | H37: 0.88607595 | I37: 9 | J37: 72 | K37: 147 | L37: 2.0416667 | M37: 25 | N37: 0.3164557
A38: Diab III | B38: 46032 | C38: 2024 | D38: Ereny Awny Fouad Ibrahim Beshara | E38: DIAB-III ALEX EAST-A | F38: 76 | G38: 72 | H38: 0.94736842 | I38: 4 | J38: 73 | K38: 163 | L38: 2.2328767 | M38: 63 | N38: 0.82894737
A39: Diab III | B39: 12-Apr-2025 | C39: 1587 | D39: Rana Mohamed Gaber AbdelHamid | E39: DIAB-III ALEX EAST-B | F39: 67 | G39: 66 | H39: 0.98507463 | I39: 1 | J39: 67 | K39: 129 | L39: 1.9253731 | M39: 64 | N39: 0.95522388
A40: Diab III | B40: 46023 | C40: 2023 | D40: Mohamed Hussein AbdelNaiem Ahmed AbdelNaiem | E40: DIAB-III ALEX WEST | F40: 68 | G40: 59 | H40: 0.86764706 | I40: 9 | J40: 60 | K40: 120 | L40: 2 | M40: 43 | N40: 0.63235294
A41: Diab III | B41: 16-Aug-2025 | C41: 1757 | D41: Ingy Mahmoud Mohamed Ahmed ElSheikh | E41: DIAB-III ALEX CENTER-B | F41: 70 | G41: 66 | H41: 0.94285714 | I41: 4 | J41: 66 | K41: 122 | L41: 1.8484848 | M41: 56 | N41: 0.8
...

Sheet Sheet1
A1: Line | B1: Experience | C1: Probation Period | D1: Hiring Date | E1: Code | F1: Employee Name | G1: Target Customers (Experienced) | H1: Target Customers Visited (Experienced) | I1: Fully Covered Customers (Experienced) | J1: District Manager | K1: National Sales Manager | L1: Business Unit | M1: Area | N1: Target Customers | O1: Target Customers Visited | P1: Target Customers Visit Coverage % | Q1: Not Covered Customers | R1: Visited Customers | S1: Actual Visits | T1: Visits per Customer | U1: Fully Covered Customers | V1: ECRP%
A3: Diab III | B3: 7 | C3: Non-Probation | D3: 12-Jul-2025 | E3: 1707 | F3: AbdelMoneim Sayed AbdelMoneim Sayed Darwish | G3: 79 | H3: 76 | I3: 63 | J3: Peter AbdelNasser Fathy Habel | K3: Mahmoud Abdel Aziz El-Sayed Mohamed | L3: Kamal El-Din Magdy Abdel Fatah Allam | M3: DIAB-III ABBASEIA-KOBBAH | N3: 79 | O3: 76 | P3: 0.96202532 | Q3: 3 | R3: 76 | S3: 169 | T3: 2.2236842 | U3: 63 | V3: 0.79746835
A4: Diab III | B4: 20 | C4: Non-Probation | D4: 22-Jun-2024 | E4: 1188 | F4: Mahmoud Mohamed Abdelmahdy Abdullah | G4: 71 | H4: 66 | I4: 40 | J4: Peter AbdelNasser Fathy Habel | K4: Mahmoud Abdel Aziz El-Sayed Mohamed | L4: Kamal El-Din Magdy Abdel Fatah Allam | M4: DIAB-III CAIRO EAST | N4: 71 | O4: 66 | P4: 0.92957746 | Q4: 5 | R4: 71 | S4: 161 | T4: 2.2676056 | U4: 40 | V4: 0.56338028
A5: Diab III | B5: 15 | C5: Non-Probation | D5: 1-Dec-2024 | E5: 1331 | F5: Yasmin Sayed AbdelLatif Mohamed Hekal | G5: 72 | H5: 68 | I5: 60 | J5: Peter AbdelNasser Fathy Habel | K5: Mahmoud Abdel Aziz El-Sayed Mohamed | L5: Kamal El-Din Magdy Abdel Fatah Allam | M5: DIAB-III AIN SHAMS | N5: 72 | O5: 68 | P5: 0.94444444 | Q5: 4 | R5: 68 | S5: 158 | T5: 2.3235294 | U5: 60 | V5: 0.83333333
A6: Diab III | B6: 2 | C6: Probation | D6: 46025 | E6: 2008 | F6: Guirgis Samir Azmy Iskandar | G6: 0 | H6: 0 | I6: 0 | J6: Peter AbdelNasser Fathy Habel | K6: Mahmoud Abdel Aziz El-Sayed Mohamed | L6: Kamal El-Din Magdy Abdel Fatah Allam | M6: DIAB-III HELIOPOLIS-A | N6: 74 | O6: 65 | P6: 0.87837838 | Q6: 9 | R6: 74 | S6: 134 | T6: 1.8108108 | U6: 27 | V6: 0.36486486
A7: Diab III | B7: 17 | C7: Non-Probation | D7: 7-Sept-2024 | E7: 1268 | F7: Mariam Makram Ragheb Soliman | G7: 80 | H7: 77 | I7: 44 | J7: Peter AbdelNasser Fathy Habel | K7: Mahmoud Abdel Aziz El-Sayed Mohamed | L7: Kamal El-Din Magdy Abdel Fatah Allam | M7: DIAB-III HELIOPOLIS-B | N7: 80 | O7: 77 | P7: 0.9625 | Q7: 3 | R7: 77 | S7: 154 | T7: 2 | U7: 44 | V7: 0.55
A8: Diab III | B8: 26 | C8: Non-Probation | D8: 1-Jan-2024 | E8: 1006 | F8: Kholoud El-Matarawy Mohamed Aly | G8: 78 | H8: 71 | I8: 48 | J8: Peter AbdelNasser Fathy Habel | K8: Mahmoud Abdel Aziz El-Sayed Mohamed | L8: Kamal El-Din Magdy Abdel Fatah Allam | M8: DIAB-III NEW CAIRO | N8: 78 | O8: 71 | P8: 0.91025641 | Q8: 7 | R8: 73 | S8: 154 | T8: 2.109589 | U8: 48 | V8: 0.61538462
A9: Diab III | B9: 1 | C9: Probation | D9: 46032 | E9: 2007 | F9: Rania Helmy Lotfy Mohamed ElAsour | G9: 0 | H9: 0 | I9: 0 | J9: Peter AbdelNasser Fathy Habel | K9: Mahmoud Abdel Aziz El-Sayed Mohamed | L9: Kamal El-Din Magdy Abdel Fatah Allam | M9: DIAB-III ISMAILIA-SUIZ | N9: 89 | O9: 53 | P9: 0.59550562 | Q9: 36 | R9: 53 | S9: 66 | T9: 1.245283 | U9: 8 | V9: 0.08988764
A10: Diab III | B10: 4 | C10: Non-Probation | D10: 2-Nov-2025 | E10: 1839 | F10: Eman Hamdy Shahat Esmail | G10: 73 | H10: 71 | I10: 39 | J10: Ahmed Adel Hosny Hassan | K10: Mahmoud Abdel Aziz El-Sayed Mohamed | L10: Kamal El-Din Magdy Abdel Fatah Allam | M10: DIAB-III CAIRO WEST | N10: 73 | O10: 71 | P10: 0.97260274 | Q10: 2 | R10: 71 | S10: 144 | T10: 2.028169 | U10: 39 | V10: 0.53424658
A11: Diab III | B11: 2 | C11: Probation | D11: 46023 | E11: 2018 | F11: Mohamed Mostafa Mohamed Mahmoud Azzam | G11: 0 | H11: 0 | I11: 0 | J11: Ahmed Adel Hosny Hassan | K11: Mahmoud Abdel Aziz El-Sayed Mohamed | L11: Kamal El-Din Magdy Abdel Fatah Allam | M11: DIAB-III CAIRO CENTER | N11: 74 | O11: 63 | P11: 0.85135135 | Q11: 11 | R11: 63 | S11: 120 | T11: 1.9047619 | U11: 40 | V11: 0.54054054
A12: Diab III | B12: 1 | C12: Probation | D12: 46032 | E12: 2074 | F12: Asmaa ElBel Zanaty Hussein Aly | G12: 0 | H12: 0 | I12: 0 | J12: Ahmed Adel Hosny Hassan | K12: Mahmoud Abdel Aziz El-Sayed Mohamed | L12: Kamal El-Din Magdy Abdel Fatah Allam | M12: DIAB-III CAIRO SOUTH | N12: 95 | O12: 78 | P12: 0.82105263 | Q12: 17 | R12: 78 | S12: 131 | T12: 1.6794872 | U12: 24 | V12: 0.25263158
A13: Diab III | B13: 66 | C13: Non-Probation | D13: 29-Aug-2020 | E13: 230 | F13: Nourhan Ashraf Mostafa Hassan | G13: 58 | H13: 0 | I13: 0 | J13: Ahmed Adel Hosny Hassan | K13: Mahmoud Abdel Aziz El-Sayed Mohamed | L13: Kamal El-Din Magdy Abdel Fatah Allam | M13: DIAB-III MAADI | N13: 58 | O13: 0 | P13: 0 | Q13: 58 | R13: 0 | S13: 0 | T13: 0 | U13: 0 | V13: 0
A14: Diab III | B14: 26 | C14: Non-Probation | D14: 1-Jan-2024 | E14: 964 | F14: Fatma Fawzy Mohamed Mahmoud | G14: 79 | H14: 69 | I14: 32 | J14: Ahmed Adel Hosny Hassan | K14: Mahmoud Abdel Aziz El-Sayed Mohamed | L14: Kamal El-Din Magdy Abdel Fatah Allam | M14: DIAB-III HELWAN | N14: 79 | O14: 69 | P14: 0.87341772 | Q14: 10 | R14: 69 | S14: 127 | T14: 1.8405797 | U14: 32 | V14: 0.40506329
A15: Diab III | B15: 1 | C15: Probation | D15: 46033 | E15: 2075 | F15: Maha Magdy AbdelSalam Mahmoud Farag | G15: 0 | H15: 0 | I15: 0 | J15: Ahmed Adel Hosny Hassan | K15: Mahmoud Abdel Aziz El-Sayed Mohamed | L15: Kamal El-Din Magdy Abdel Fatah Allam | M15: DIAB-III QALUBIA-A | N15: 77 | O15: 74 | P15: 0.96103896 | Q15: 3 | R15: 75 | S15: 164 | T15: 2.1866667 | U15: 43 | V15: 0.55844156
A16: Diab III | B16: 2 | C16: Probation | D16: 46023 | E16: 2019 | F16: Mahmoud Lotfy Saied AbdelFatah | G16: 0 | H16: 0 | I16: 0 | J16: Ahmed Adel Hosny Hassan | K16: Mahmoud Abdel Aziz El-Sayed Mohamed | L16: Kamal El-Din Magdy Abdel Fatah Allam | M16: DIAB-III QALUBIA-B | N16: 82 | O16: 76 | P16: 0.92682927 | Q16: 6 | R16: 77 | S16: 147 | T16: 1.9090909 | U16: 42 | V16: 0.51219512
A17: Diab III | B17: 18 | C17: Non-Probation | D17: 10-Aug-2024 | E17: 1248 | F17: Mariam AbdelRahman Abdel Samie Abdel Wadod | G17: 102 | H17: 93 | I17: 57 | J17: Vacant_Delta 1 | K17: Mahmoud Abdel Aziz El-Sayed Mohamed | L17: Kamal El-Din Magdy Abdel Fatah Allam | M17: DIAB-III SHARKIA-A | N17: 102 | O17: 93 | P17: 0.91176471 | Q17: 9 | R17: 93 | S17: 163 | T17: 1.7526882 | U17: 57 | V17: 0.55882353
A18: Diab III | B18: 2 | C18: Probation | D18: 46023 | E18: 2020 | F18: Youssef AbdelBaset Esmail Ahmed Ammar Badran | G18: 0 | H18: 0 | I18: 0 | J18: Vacant_Delta 1 | K18: Mahmoud Abdel Aziz El-Sayed Mohamed | L18: Kamal El-Din Magdy Abdel Fatah Allam | M18: DIAB-III SHARKIA-B | N18: 95 | O18: 75 | P18: 0.78947368 | Q18: 20 | R18: 83 | S18: 156 | T18: 1.8795181 | U18: 46 | V18: 0.48421053
A19: Diab III | B19: 1 | C19: Probation | D19: 46032 | E19: 2039 | F19: Anas Mohamed ElSayed Ibrahim Salem | G19: 0 | H19: 0 | I19: 0 | J19: Vacant_Delta 1 | K19: Mahmoud Abdel Aziz El-Sayed Mohamed | L19: Kamal El-Din Magdy Abdel Fatah Allam | M19: DIAB-III SHARKIA-C | N19: 83 | O19: 66 | P19: 0.79518072 | Q19: 17 | R19: 82 | S19: 131 | T19: 1.597561 | U19: 31 | V19: 0.37349398
A20: Diab III | B20: 26 | C20: Non-Probation | D20: 1-Jan-2024 | E20: 1047 | F20: Alaa Aly Aly Abu El-Enein | G20: 87 | H20: 86 | I20: 56 | J20: Vacant_Delta 1 | K20: Mahmoud Abdel Aziz El-Sayed Mohamed | L20: Kamal El-Din Magdy Abdel Fatah Allam | M20: DIAB-III DAKAHLIA-A | N20: 87 | O20: 86 | P20: 0.98850575 | Q20: 1 | R20: 87 | S20: 158 | T20: 1.816092 | U20: 56 | V20: 0.64367816
A21: Diab III | B21: 23 | C21: Non-Probation | D21: 14-Mar-2024 | E21: 1117 | F21: Reem Hassan Tolba Ibrahim | G21: 83 | H21: 75 | I21: 55 | J21: Vacant_Delta 1 | K21: Mahmoud Abdel Aziz El-Sayed Mohamed | L21: Kamal El-Din Magdy Abdel Fatah Allam | M21: DIAB-III DAKAHLIA-B | N21: 83 | O21: 75 | P21: 0.90361446 | Q21: 8 | R21: 75 | S21: 123 | T21: 1.64 | U21: 55 | V21: 0.6626506
A22: Diab III | B22: 2 | C22: Probation | D22: 46023 | E22: 2021 | F22: Donia Mahmoud Mohamed Ahmed Mowafy | G22: 0 | H22: 0 | I22: 0 | J22: Vacant_Delta 1 | K22: Mahmoud Abdel Aziz El-Sayed Mohamed | L22: Kamal El-Din Magdy Abdel Fatah Allam | M22: DIAB-III DAKAHLIA-C | N22: 76 | O22: 76 | P22: 1 | Q22: 0 | R22: 76 | S22: 169 | T22: 2.2236842 | U22: 69 | V22: 0.90789474
A23: Diab III | B23: 67 | C23: Non-Probation | D23: 18-Jul-2020 | E23: 194 | F23: Menna Allah Hassouna Abbas Hassouna | G23: 77 | H23: 73 | I23: 27 | J23: Vacant_Delta 1 | K23: Mahmoud Abdel Aziz El-Sayed Mohamed | L23: Kamal El-Din Magdy Abdel Fatah Allam | M23: DIAB-III DOMIAT | N23: 77 | O23: 73 | P23: 0.94805195 | Q23: 4 | R23: 73 | S23: 163 | T23: 2.2328767 | U23: 27 | V23: 0.35064935
A24: Diab III | B24: 26 | C24: Non-Probation | D24: 1-Jan-2024 | E24: 998 | F24: Shereen Tarek Gouda El-Sayed | G24: 66 | H24: 61 | I24: 19 | J24: Vacant_Delta 1 | K24: Mahmoud Abdel Aziz El-Sayed Mohamed | L24: Kamal El-Din Magdy Abdel Fatah Allam | M24: DIAB-III P. SAID-N. SINAI | N24: 66 | O24: 61 | P24: 0.92424242 | Q24: 5 | R24: 62 | S24: 150 | T24: 2.4193548 | U24: 19 | V24: 0.28787879
A25: Diab III | B25: 2 | C25: Probation | D25: 46023 | E25: 1992 | F25: Mostafa Mahmoud Gaber ElHajjar | G25: 0 | H25: 0 | I25: 0 | J25: Mohamed ElSayed Mostafa Gaber | K25: Mahmoud Abdel Aziz El-Sayed Mohamed | L25: Kamal El-Din Magdy Abdel Fatah Allam | M25: DIAB-III MENOFYA-A | N25: 78 | O25: 68 | P25: 0.87179487 | Q25: 10 | R25: 81 | S25: 162 | T25: 2 | U25: 38 | V25: 0.48717949
A26: Diab III | B26: 2 | C26: Probation | D26: 46023 | E26: 1995 | F26: Zeinab Serry AbdelSamie Ammar | G26: 0 | H26: 0 | I26: 0 | J26: Mohamed ElSayed Mostafa Gaber | K26: Mahmoud Abdel Aziz El-Sayed Mohamed | L26: Kamal El-Din Magdy Abdel Fatah Allam | M26: DIAB-III MENOFYA-B | N26: 72 | O26: 66 | P26: 0.91666667 | Q26: 6 | R26: 78 | S26: 155 | T26: 1.9871795 | U26: 48 | V26: 0.66666667
A27: Diab III | B27: 2 | C27: Probation | D27: 46023 | E27: 1994 | F27: Mariam AbuElMagd Ibrahim Abdullah ElNaggar | G27: 0 | H27: 0 | I27: 0 | J27: Mohamed ElSayed Mostafa Gaber | K27: Mahmoud Abdel Aziz El-Sayed Mohamed | L27: Kamal El-Din Magdy Abdel Fatah Allam | M27: DIAB-III GHARBIA-B | N27: 96 | O27: 69 | P27: 0.71875 | Q27: 27 | R27: 75 | S27: 139 | T27: 1.8533333 | U27: 38 | V27: 0.39583333
A28: Diab III | B28: 2 | C28: Probation | D28: 46023 | E28: 1993 | F28: Mohamed Ahmed ElSayed Ahmed ElTaras | G28: 0 | H28: 0 | I28: 0 | J28: Mohamed ElSayed Mostafa Gaber | K28: Mahmoud Abdel Aziz El-Sayed Mohamed | L28: Kamal El-Din Magdy Abdel Fatah Allam | M28: DIAB-III GHARBIA-A | N28: 90 | O28: 53 | P28: 0.58888889 | Q28: 37 | R28: 86 | S28: 141 | T28: 1.6395349 | U28: 20 | V28: 0.22222222
A29: Diab III | B29: 1 | C29: Probation | D29: 46054 | E29: 2133 | F29: Hazem Mohamed HasaBallah Esmail Ibrahim | G29: 0 | H29: 0 | I29: 0 | J29: Mohamed ElSayed Mostafa Gaber | K29: Mahmoud Abdel Aziz El-Sayed Mohamed | L29: Kamal El-Din Magdy Abdel Fatah Allam | M29: DIAB-III KAFR ELSHEIKH-A | N29: 71 | O29: 31 | P29: 0.43661972 | Q29: 40 | R29: 36 | S29: 40 | T29: 1.1111111 | U29: 6 | V29: 0.084507042
A30: Diab III | B30: 28 | C30: Non-Probation | D30: 2-Nov-2023 | E30: 940 | F30: Mohamed Mohamed Mohamed Hassan Salah | G30: 79 | H30: 70 | I30: 25 | J30: Mohamed ElSayed Mostafa Gaber | K30: Mahmoud Abdel Aziz El-Sayed Mohamed | L30: Kamal El-Din Magdy Abdel Fatah Allam | M30: DIAB-III KAFR ELSHEIKH-B | N30: 79 | O30: 70 | P30: 0.88607595 | Q30: 9 | R30: 72 | S30: 147 | T30: 2.0416667 | U30: 25 | V30: 0.3164557
A31: Diab III | B31: 1 | C31: Probation | D31: 46032 | E31: 2024 | F31: Ereny Awny Fouad Ibrahim Beshara | G31: 0 | H31: 0 | I31: 0 | J31: Karim Mohamed Nagib Mohamed El-Demerdash | K31: Mahmoud Abdel Aziz El-Sayed Mohamed | L31: Kamal El-Din Magdy Abdel Fatah Allam | M31: DIAB-III ALEX EAST-A | N31: 76 | O31: 72 | P31: 0.94736842 | Q31: 4 | R31: 73 | S31: 163 | T31: 2.2328767 | U31: 63 | V31: 0.82894737
A32: Diab III | B32: 10 | C32: Non-Probation | D32: 12-Apr-2025 | E32: 1587 | F32: Rana Mohamed Gaber AbdelHamid | G32: 67 | H32: 66 | I32: 64 | J32: Karim Mohamed Nagib Mohamed El-Demerdash | K32: Mahmoud Abdel Aziz El-Sayed Mohamed | L32: Kamal El-Din Magdy Abdel Fatah Allam | M32: DIAB-III ALEX EAST-B | N32: 67 | O32: 66 | P32: 0.98507463 | Q32: 1 | R32: 67 | S32: 129 | T32: 1.9253731 | U32: 64 | V32: 0.95522388
A33: Diab III | B33: 2 | C33: Probation | D33: 46023 | E33: 2023 | F33: Mohamed Hussein AbdelNaiem Ahmed AbdelNaiem | G33: 0 | H33: 0 | I33: 0 | J33: Karim Mohamed Nagib Mohamed El-Demerdash | K33: Mahmoud Abdel Aziz El-Sayed Mohamed | L33: Kamal El-Din Magdy Abdel Fatah Allam | M33: DIAB-III ALEX WEST | N33: 68 | O33: 59 | P33: 0.86764706 | Q33: 9 | R33: 60 | S33: 120 | T33: 2 | U33: 43 | V33: 0.63235294
A34: Diab III | B34: 6 | C34: Non-Probation | D34: 16-Aug-2025 | E34: 1757 | F34: Ingy Mahmoud Mohamed Ahmed ElSheikh | G34: 70 | H34: 66 | I34: 56 | J34: Karim Mohamed Nagib Mohamed El-Demerdash | K34: Mahmoud Abdel Aziz El-Sayed Mohamed | L34: Kamal El-Din Magdy Abdel Fatah Allam | M34: DIAB-III ALEX CENTER-B | N34: 70 | O34: 66 | P34: 0.94285714 | Q34: 4 | R34: 66 | S34: 122 | T34: 1.8484848 | U34: 56 | V34: 0.8
A35: Diab III | B35: 26 | C35: Non-Probation | D35: 1-Jan-2024 | E35: 970 | F35: Marwa Mohamed Hussien Abdel Karim | G35: 71 | H35: 71 | I35: 52 | J35: Karim Mohamed Nagib Mohamed El-Demerdash | K35: Mahmoud Abdel Aziz El-Sayed Mohamed | L35: Kamal El-Din Magdy Abdel Fatah Allam | M35: DIAB-II BEHIRA-A | N35: 71 | O35: 71 | P35: 1 | Q35: 0 | R35: 71 | S35: 129 | T35: 1.8169014 | U35: 52 | V35: 0.73239437
A36: Diab III | B36: 33 | C36: Non-Probation | D36: 20-May-2023 | E36: 788 | F36: Monica Ibrahim Guirgis Youssef | G36: 66 | H36: 66 | I36: 49 | J36: Karim Mohamed Nagib Mohamed El-Demerdash | K36: Mahmoud Abdel Aziz El-Sayed Mohamed | L36: Kamal El-Din Magdy Abdel Fatah Allam | M36: DIAB-II BEHIRA-B | N36: 66 | O36: 66 | P36: 1 | Q36: 0 | R36: 66 | S36: 121 | T36: 1.8333333 | U36: 49 | V36: 0.74242424
A37: Diab III | B37: 1 | C37: Probation | D37: 46032 | E37: 2092 | F37: Mohamed Ayman Mohamed Mahmoud AbuShosha | G37: 0 | H37: 0 | I37: 0 | J37: Karim Mohamed Nagib Mohamed El-Demerdash | K37: Mahmoud Abdel Aziz El-Sayed Mohamed | L37: Kamal El-Din Magdy Abdel Fatah Allam | M37: DIAB-II BEHIRA-C | N37: 63 | O37: 59 | P37: 0.93650794 | Q37: 4 | R37: 67 | S37: 155 | T37: 2.3134328 | U37: 47 | V37: 0.74603175
A38: Diab III | B38: 33 | C38: Non-Probation | D38: 27-May-2023 | E38: 789 | F38: Kyrilles Latif Masoud Yassa | G38: 75 | H38: 71 | I38: 47 | J38: Jacklyn Mamdouh Aziz Loka | K38: Mahmoud Abdel Aziz El-Sayed Mohamed | L38: Kamal El-Din Magdy Abdel Fatah Allam | M38: DIAB-III HARAM-GIZA CENTERS | N38: 75 | O38: 71 | P38: 0.94666667 | Q38: 4 | R38: 76 | S38: 131 | T38: 1.7236842 | U38: 47 | V38: 0.62666667
A39: Diab III | B39: 24 | C39: Non-Probation | D39: 2-Mar-2024 | E39: 1114 | F39: Mostafa Khaled Mohamed Mohamed | G39: 75 | H39: 73 | I39: 56 | J39: Jacklyn Mamdouh Aziz Loka | K39: Mahmoud Abdel Aziz El-Sayed Mohamed | L39: Kamal El-Din Magdy Abdel Fatah Allam | M39: DIAB-III MOHANDSEEN | N39: 75 | O39: 73 | P39: 0.97333333 | Q39: 2 | R39: 75 | S39: 144 | T39: 1.92 | U39: 56 | V39: 0.74666667
A40: Diab III | B40: 0 | C40: Probation | D40: 46066 | E40: 2132 | F40: Amin Ibrahim Mohamed Amin | G40: 0 | H40: 0 | I40: 0 | J40: Jacklyn Mamdouh Aziz Loka | K40: Mahmoud Abdel Aziz El-Sayed Mohamed | L40: Kamal El-Din Magdy Abdel Fatah Allam | M40: DIAB-III FAISAL | N40: 77 | O40: 5 | P40: 0.064935065 | Q40: 72 | R40: 6 | S40: 6 | T40: 1 | U40: 0 | V40: 0
A41: Diab III | B41: 2 | C41: Probation | D41: 46023 | E41: 2009 | F41: Kamar AbdelSamie AbdelWahed Sawy | G41: 0 | H41: 0 | I41: 0 | J41: Vacant Upper Egypt B | K41: Mahmoud Abdel Aziz El-Sayed Mohamed | L41: Kamal El-Din Magdy Abdel Fatah Allam | M41: DIAB-III MENIA-A | N41: 84 | O41: 79 | P41: 0.94047619 | Q41: 5 | R41: 79 | S41: 164 | T41: 2.0759494 | U41: 42 | V41: 0.5
...

Sheet sheet
A1: Line | B1: Hiring Date | C1: Code | D1: Name | E1: Area | F1: Target Customers | G1: Target Customers Visited | H1: Target Customers Visit Coverage % | I1: Not Covered Customers | J1: Visited Customers | K1: Actual Visits | L1: Visits per Customer | M1: Fully Covered Customers | N1: ECRP%
A3: Diab III | B3: 12-Jul-2025 | C3: 1707 | D3: AbdelMoneim Sayed AbdelMoneim Sayed Darwish | E3: DIAB-III ABBASEIA-KOBBAH | F3: =VLOOKUP(D3,Coverage!A:B,2,0) -> 79 | G3: =VLOOKUP(D3,Coverage!A:C,3,0) -> 76 | H3: =VLOOKUP(D3,Coverage!A:D,4,0) -> 0.96202532 | I3: =VLOOKUP(D3,Coverage!A:E,5,0) -> 3 | J3: =VLOOKUP(D3,Coverage!A:F,6,0) -> 76 | K3: =VLOOKUP(D3,Coverage!A:G,7,0) -> 169 | L3: =VLOOKUP(D3,Coverage!A:H,8,0) -> 2.2236842 | M3: =VLOOKUP(D3,Coverage!A:I,9,0) -> 63 | N3: =M3/F3 -> 0.79746835
A4: Diab III | B4: 22-Jun-2024 | C4: 1188 | D4: Mahmoud Mohamed Abdelmahdy Abdullah | E4: DIAB-III CAIRO EAST | F4: =VLOOKUP(D4,Coverage!A:B,2,0) -> 71 | G4: =VLOOKUP(D4,Coverage!A:C,3,0) -> 66 | H4: =VLOOKUP(D4,Coverage!A:D,4,0) -> 0.92957746 | I4: =VLOOKUP(D4,Coverage!A:E,5,0) -> 5 | J4: =VLOOKUP(D4,Coverage!A:F,6,0) -> 71 | K4: =VLOOKUP(D4,Coverage!A:G,7,0) -> 161 | L4: =VLOOKUP(D4,Coverage!A:H,8,0) -> 2.2676056 | M4: =VLOOKUP(D4,Coverage!A:I,9,0) -> 40 | N4: =M4/F4 -> 0.56338028
A5: Diab III | B5: 1-Dec-2024 | C5: 1331 | D5: Yasmin Sayed AbdelLatif Mohamed Hekal | E5: DIAB-III AIN SHAMS | F5: =VLOOKUP(D5,Coverage!A:B,2,0) -> 72 | G5: =VLOOKUP(D5,Coverage!A:C,3,0) -> 68 | H5: =VLOOKUP(D5,Coverage!A:D,4,0) -> 0.94444444 | I5: =VLOOKUP(D5,Coverage!A:E,5,0) -> 4 | J5: =VLOOKUP(D5,Coverage!A:F,6,0) -> 68 | K5: =VLOOKUP(D5,Coverage!A:G,7,0) -> 158 | L5: =VLOOKUP(D5,Coverage!A:H,8,0) -> 2.3235294 | M5: =VLOOKUP(D5,Coverage!A:I,9,0) -> 60 | N5: =M5/F5 -> 0.83333333
A6: Diab III | B6: 46025 | C6: 2008 | D6: Guirgis Samir Azmy Iskandar | E6: DIAB-III HELIOPOLIS-A | F6: =VLOOKUP(D6,Coverage!A:B,2,0) -> 74 | G6: =VLOOKUP(D6,Coverage!A:C,3,0) -> 65 | H6: =VLOOKUP(D6,Coverage!A:D,4,0) -> 0.87837838 | I6: =VLOOKUP(D6,Coverage!A:E,5,0) -> 9 | J6: =VLOOKUP(D6,Coverage!A:F,6,0) -> 74 | K6: =VLOOKUP(D6,Coverage!A:G,7,0) -> 134 | L6: =VLOOKUP(D6,Coverage!A:H,8,0) -> 1.8108108 | M6: =VLOOKUP(D6,Coverage!A:I,9,0) -> 27 | N6: =M6/F6 -> 0.36486486
A7: Diab III | B7: 7-Sept-2024 | C7: 1268 | D7: Mariam Makram Ragheb Soliman | E7: DIAB-III HELIOPOLIS-B | F7: =VLOOKUP(D7,Coverage!A:B,2,0) -> 80 | G7: =VLOOKUP(D7,Coverage!A:C,3,0) -> 77 | H7: =VLOOKUP(D7,Coverage!A:D,4,0) -> 0.9625 | I7: =VLOOKUP(D7,Coverage!A:E,5,0) -> 3 | J7: =VLOOKUP(D7,Coverage!A:F,6,0) -> 77 | K7: =VLOOKUP(D7,Coverage!A:G,7,0) -> 154 | L7: =VLOOKUP(D7,Coverage!A:H,8,0) -> 2 | M7: =VLOOKUP(D7,Coverage!A:I,9,0) -> 44 | N7: =M7/F7 -> 0.55
A8: Diab III | D8: Vacant_NasrCity | E8: DIAB-III NASR CITY | F8: =VLOOKUP(D8,Coverage!A:B,2,0) -> #N/A | G8: =VLOOKUP(D8,Coverage!A:C,3,0) -> #N/A | H8: =VLOOKUP(D8,Coverage!A:D,4,0) -> #N/A | I8: =VLOOKUP(D8,Coverage!A:E,5,0) -> #N/A | J8: =VLOOKUP(D8,Coverage!A:F,6,0) -> #N/A | K8: =VLOOKUP(D8,Coverage!A:G,7,0) -> #N/A | L8: =VLOOKUP(D8,Coverage!A:H,8,0) -> #N/A | M8: =VLOOKUP(D8,Coverage!A:I,9,0) -> #N/A | N8: =M8/F8 -> #N/A
A9: Diab III | B9: 1-Jan-2024 | C9: 1006 | D9: Kholoud El-Matarawy Mohamed Aly | E9: DIAB-III NEW CAIRO | F9: =VLOOKUP(D9,Coverage!A:B,2,0) -> 78 | G9: =VLOOKUP(D9,Coverage!A:C,3,0) -> 71 | H9: =VLOOKUP(D9,Coverage!A:D,4,0) -> 0.91025641 | I9: =VLOOKUP(D9,Coverage!A:E,5,0) -> 7 | J9: =VLOOKUP(D9,Coverage!A:F,6,0) -> 73 | K9: =VLOOKUP(D9,Coverage!A:G,7,0) -> 154 | L9: =VLOOKUP(D9,Coverage!A:H,8,0) -> 2.109589 | M9: =VLOOKUP(D9,Coverage!A:I,9,0) -> 48 | N9: =M9/F9 -> 0.61538462
A10: Diab III | B10: 46032 | C10: 2007 | D10: Rania Helmy Lotfy Mohamed ElAsour | E10: DIAB-III ISMAILIA-SUIZ | F10: =VLOOKUP(D10,Coverage!A:B,2,0) -> 89 | G10: =VLOOKUP(D10,Coverage!A:C,3,0) -> 53 | H10: =VLOOKUP(D10,Coverage!A:D,4,0) -> 0.59550562 | I10: =VLOOKUP(D10,Coverage!A:E,5,0) -> 36 | J10: =VLOOKUP(D10,Coverage!A:F,6,0) -> 53 | K10: =VLOOKUP(D10,Coverage!A:G,7,0) -> 66 | L10: =VLOOKUP(D10,Coverage!A:H,8,0) -> 1.245283 | M10: =VLOOKUP(D10,Coverage!A:I,9,0) -> 8 | N10: =M10/F10 -> 0.08988764
A11: Diab III | B11: 1-Feb-2025 | C11: 1439 | D11: Peter AbdelNasser Fathy Habel | E11: DIAB-III DM CAIRO B | F11: =SUM(F9,F7,F3:F5) -> 380 | G11: =SUM(G9,G7,G3:G5) -> 358 | H11: =G11/F11 -> 0.94210526 | I11: =SUM(I9,I7,I3:I5) -> 22 | J11: =SUM(J9,J7,J3:J5) -> 365 | K11: =SUM(K9,K7,K3:K5) -> 796 | L11: =AVERAGE(L9,L7,L3:L5) -> 2.1848817 | M11: =SUM(M9,M7,M3:M5) -> 255 | N11: =M11/F11 -> 0.67105263
A12: Diab III | D12: Vacant_Shoubraelkhemah | E12: DIAB-III SHOBRA EL KHEMAH | F12: =VLOOKUP(D12,Coverage!A:B,2,0) -> #N/A | G12: =VLOOKUP(D12,Coverage!A:C,3,0) -> #N/A | H12: =VLOOKUP(D12,Coverage!A:D,4,0) -> #N/A | I12: =VLOOKUP(D12,Coverage!A:E,5,0) -> #N/A | J12: =VLOOKUP(D12,Coverage!A:F,6,0) -> #N/A | K12: =VLOOKUP(D12,Coverage!A:G,7,0) -> #N/A | L12: =VLOOKUP(D12,Coverage!A:H,8,0) -> #N/A | M12: =VLOOKUP(D12,Coverage!A:I,9,0) -> #N/A | N12: =M12/F12 -> #N/A
A13: Diab III | B13: 2-Nov-2025 | C13: 1839 | D13: Eman Hamdy Shahat Esmail | E13: DIAB-III CAIRO WEST | F13: =VLOOKUP(D13,Coverage!A:B,2,0) -> 73 | G13: =VLOOKUP(D13,Coverage!A:C,3,0) -> 71 | H13: =VLOOKUP(D13,Coverage!A:D,4,0) -> 0.97260274 | I13: =VLOOKUP(D13,Coverage!A:E,5,0) -> 2 | J13: =VLOOKUP(D13,Coverage!A:F,6,0) -> 71 | K13: =VLOOKUP(D13,Coverage!A:G,7,0) -> 144 | L13: =VLOOKUP(D13,Coverage!A:H,8,0) -> 2.028169 | M13: =VLOOKUP(D13,Coverage!A:I,9,0) -> 39 | N13: =M13/F13 -> 0.53424658
A14: Diab III | B14: 46023 | C14: 2018 | D14: Mohamed Mostafa Mohamed Mahmoud Azzam | E14: DIAB-III CAIRO CENTER | F14: =VLOOKUP(D14,Coverage!A:B,2,0) -> 74 | G14: =VLOOKUP(D14,Coverage!A:C,3,0) -> 63 | H14: =VLOOKUP(D14,Coverage!A:D,4,0) -> 0.85135135 | I14: =VLOOKUP(D14,Coverage!A:E,5,0) -> 11 | J14: =VLOOKUP(D14,Coverage!A:F,6,0) -> 63 | K14: =VLOOKUP(D14,Coverage!A:G,7,0) -> 120 | L14: =VLOOKUP(D14,Coverage!A:H,8,0) -> 1.9047619 | M14: =VLOOKUP(D14,Coverage!A:I,9,0) -> 40 | N14: =M14/F14 -> 0.54054054
A15: Diab III | B15: 46032 | C15: 2074 | D15: Asmaa ElBel Zanaty Hussein Aly | E15: DIAB-III CAIRO SOUTH | F15: =VLOOKUP(D15,Coverage!A:B,2,0) -> 95 | G15: =VLOOKUP(D15,Coverage!A:C,3,0) -> 78 | H15: =VLOOKUP(D15,Coverage!A:D,4,0) -> 0.82105263 | I15: =VLOOKUP(D15,Coverage!A:E,5,0) -> 17 | J15: =VLOOKUP(D15,Coverage!A:F,6,0) -> 78 | K15: =VLOOKUP(D15,Coverage!A:G,7,0) -> 131 | L15: =VLOOKUP(D15,Coverage!A:H,8,0) -> 1.6794872 | M15: =VLOOKUP(D15,Coverage!A:I,9,0) -> 24 | N15: =M15/F15 -> 0.25263158
A16: Diab III | B16: 29-Aug-2020 | C16: 230 | D16: Nourhan Ashraf Mostafa Hassan | E16: DIAB-III MAADI | F16: =VLOOKUP(D16,Coverage!A:B,2,0) -> 58 | G16: =VLOOKUP(D16,Coverage!A:C,3,0) -> 0 | H16: =VLOOKUP(D16,Coverage!A:D,4,0) -> 0 | I16: =VLOOKUP(D16,Coverage!A:E,5,0) -> 58 | J16: =VLOOKUP(D16,Coverage!A:F,6,0) -> 0 | K16: =VLOOKUP(D16,Coverage!A:G,7,0) -> 0 | L16: =VLOOKUP(D16,Coverage!A:H,8,0) -> 0 | M16: =VLOOKUP(D16,Coverage!A:I,9,0) -> 0 | N16: =M16/F16 -> 0
A17: Diab III | B17: 1-Jan-2024 | C17: 964 | D17: Fatma Fawzy Mohamed Mahmoud | E17: DIAB-III HELWAN | F17: =VLOOKUP(D17,Coverage!A:B,2,0) -> 79 | G17: =VLOOKUP(D17,Coverage!A:C,3,0) -> 69 | H17: =VLOOKUP(D17,Coverage!A:D,4,0) -> 0.87341772 | I17: =VLOOKUP(D17,Coverage!A:E,5,0) -> 10 | J17: =VLOOKUP(D17,Coverage!A:F,6,0) -> 69 | K17: =VLOOKUP(D17,Coverage!A:G,7,0) -> 127 | L17: =VLOOKUP(D17,Coverage!A:H,8,0) -> 1.8405797 | M17: =VLOOKUP(D17,Coverage!A:I,9,0) -> 32 | N17: =M17/F17 -> 0.40506329
A18: Diab III | B18: 46033 | C18: 2075 | D18: Maha Magdy AbdelSalam Mahmoud Farag | E18: DIAB-III QALUBIA-A | F18: =VLOOKUP(D18,Coverage!A:B,2,0) -> 77 | G18: =VLOOKUP(D18,Coverage!A:C,3,0) -> 74 | H18: =VLOOKUP(D18,Coverage!A:D,4,0) -> 0.96103896 | I18: =VLOOKUP(D18,Coverage!A:E,5,0) -> 3 | J18: =VLOOKUP(D18,Coverage!A:F,6,0) -> 75 | K18: =VLOOKUP(D18,Coverage!A:G,7,0) -> 164 | L18: =VLOOKUP(D18,Coverage!A:H,8,0) -> 2.1866667 | M18: =VLOOKUP(D18,Coverage!A:I,9,0) -> 43 | N18: =M18/F18 -> 0.55844156
A19: Diab III | B19: 46023 | C19: 2019 | D19: Mahmoud Lotfy Saied AbdelFatah | E19: DIAB-III QALUBIA-B | F19: =VLOOKUP(D19,Coverage!A:B,2,0) -> 82 | G19: =VLOOKUP(D19,Coverage!A:C,3,0) -> 76 | H19: =VLOOKUP(D19,Coverage!A:D,4,0) -> 0.92682927 | I19: =VLOOKUP(D19,Coverage!A:E,5,0) -> 6 | J19: =VLOOKUP(D19,Coverage!A:F,6,0) -> 77 | K19: =VLOOKUP(D19,Coverage!A:G,7,0) -> 147 | L19: =VLOOKUP(D19,Coverage!A:H,8,0) -> 1.9090909 | M19: =VLOOKUP(D19,Coverage!A:I,9,0) -> 42 | N19: =M19/F19 -> 0.51219512
A20: Diab III | B20: 46023 | C20: 1902 | D20: Ahmed Adel Hosny Hassan | E20: DIAB-III DM CAIRO A | F20: =SUM(F16:F17,F13) -> 210 | G20: =SUM(G16:G17,G13) -> 140 | H20: =G20/F20 -> 0.66666667 | I20: =SUM(I16:I17,I13) -> 70 | J20: =SUM(J16:J17,J13) -> 140 | K20: =SUM(K16:K17,K13) -> 271 | L20: =AVERAGE(L16:L17,L13) -> 1.2895829 | M20: =SUM(M16:M17,M13) -> 71 | N20: =M20/F20 -> 0.33809524
A21: Diab III | B21: 10-Aug-2024 | C21: 1248 | D21: Mariam AbdelRahman Abdel Samie Abdel Wadod | E21: DIAB-III SHARKIA-A | F21: =VLOOKUP(D21,Coverage!A:B,2,0) -> 102 | G21: =VLOOKUP(D21,Coverage!A:C,3,0) -> 93 | H21: =VLOOKUP(D21,Coverage!A:D,4,0) -> 0.91176471 | I21: =VLOOKUP(D21,Coverage!A:E,5,0) -> 9 | J21: =VLOOKUP(D21,Coverage!A:F,6,0) -> 93 | K21: =VLOOKUP(D21,Coverage!A:G,7,0) -> 163 | L21: =VLOOKUP(D21,Coverage!A:H,8,0) -> 1.7526882 | M21: =VLOOKUP(D21,Coverage!A:I,9,0) -> 57 | N21: =M21/F21 -> 0.55882353
A22: Diab III | B22: 46023 | C22: 2020 | D22: Youssef AbdelBaset Esmail Ahmed Ammar Badran | E22: DIAB-III SHARKIA-B | F22: =VLOOKUP(D22,Coverage!A:B,2,0) -> 95 | G22: =VLOOKUP(D22,Coverage!A:C,3,0) -> 75 | H22: =VLOOKUP(D22,Coverage!A:D,4,0) -> 0.78947368 | I22: =VLOOKUP(D22,Coverage!A:E,5,0) -> 20 | J22: =VLOOKUP(D22,Coverage!A:F,6,0) -> 83 | K22: =VLOOKUP(D22,Coverage!A:G,7,0) -> 156 | L22: =VLOOKUP(D22,Coverage!A:H,8,0) -> 1.8795181 | M22: =VLOOKUP(D22,Coverage!A:I,9,0) -> 46 | N22: =M22/F22 -> 0.48421053
A23: Diab III | B23: 46032 | C23: 2039 | D23: Anas Mohamed ElSayed Ibrahim Salem | E23: DIAB-III SHARKIA-C | F23: =VLOOKUP(D23,Coverage!A:B,2,0) -> 83 | G23: =VLOOKUP(D23,Coverage!A:C,3,0) -> 66 | H23: =VLOOKUP(D23,Coverage!A:D,4,0) -> 0.79518072 | I23: =VLOOKUP(D23,Coverage!A:E,5,0) -> 17 | J23: =VLOOKUP(D23,Coverage!A:F,6,0) -> 82 | K23: =VLOOKUP(D23,Coverage!A:G,7,0) -> 131 | L23: =VLOOKUP(D23,Coverage!A:H,8,0) -> 1.597561 | M23: =VLOOKUP(D23,Coverage!A:I,9,0) -> 31 | N23: =M23/F23 -> 0.37349398
A24: Diab III | B24: 1-Jan-2024 | C24: 1047 | D24: Alaa Aly Aly Abu El-Enein | E24: DIAB-III DAKAHLIA-A | F24: =VLOOKUP(D24,Coverage!A:B,2,0) -> 87 | G24: =VLOOKUP(D24,Coverage!A:C,3,0) -> 86 | H24: =VLOOKUP(D24,Coverage!A:D,4,0) -> 0.98850575 | I24: =VLOOKUP(D24,Coverage!A:E,5,0) -> 1 | J24: =VLOOKUP(D24,Coverage!A:F,6,0) -> 87 | K24: =VLOOKUP(D24,Coverage!A:G,7,0) -> 158 | L24: =VLOOKUP(D24,Coverage!A:H,8,0) -> 1.816092 | M24: =VLOOKUP(D24,Coverage!A:I,9,0) -> 56 | N24: =M24/F24 -> 0.64367816
A25: Diab III | B25: 14-Mar-2024 | C25: 1117 | D25: Reem Hassan Tolba Ibrahim | E25: DIAB-III DAKAHLIA-B | F25: =VLOOKUP(D25,Coverage!A:B,2,0) -> 83 | G25: =VLOOKUP(D25,Coverage!A:C,3,0) -> 75 | H25: =VLOOKUP(D25,Coverage!A:D,4,0) -> 0.90361446 | I25: =VLOOKUP(D25,Coverage!A:E,5,0) -> 8 | J25: =VLOOKUP(D25,Coverage!A:F,6,0) -> 75 | K25: =VLOOKUP(D25,Coverage!A:G,7,0) -> 123 | L25: =VLOOKUP(D25,Coverage!A:H,8,0) -> 1.64 | M25: =VLOOKUP(D25,Coverage!A:I,9,0) -> 55 | N25: =M25/F25 -> 0.6626506
A26: Diab III | B26: 46023 | C26: 2021 | D26: Donia Mahmoud Mohamed Ahmed Mowafy | E26: DIAB-III DAKAHLIA-C | F26: =VLOOKUP(D26,Coverage!A:B,2,0) -> 76 | G26: =VLOOKUP(D26,Coverage!A:C,3,0) -> 76 | H26: =VLOOKUP(D26,Coverage!A:D,4,0) -> 1 | I26: =VLOOKUP(D26,Coverage!A:E,5,0) -> 0 | J26: =VLOOKUP(D26,Coverage!A:F,6,0) -> 76 | K26: =VLOOKUP(D26,Coverage!A:G,7,0) -> 169 | L26: =VLOOKUP(D26,Coverage!A:H,8,0) -> 2.2236842 | M26: =VLOOKUP(D26,Coverage!A:I,9,0) -> 69 | N26: =M26/F26 -> 0.90789474
A27: Diab III | B27: 18-Jul-2020 | C27: 194 | D27: Menna Allah Hassouna Abbas Hassouna | E27: DIAB-III DOMIAT | F27: =VLOOKUP(D27,Coverage!A:B,2,0) -> 77 | G27: =VLOOKUP(D27,Coverage!A:C,3,0) -> 73 | H27: =VLOOKUP(D27,Coverage!A:D,4,0) -> 0.94805195 | I27: =VLOOKUP(D27,Coverage!A:E,5,0) -> 4 | J27: =VLOOKUP(D27,Coverage!A:F,6,0) -> 73 | K27: =VLOOKUP(D27,Coverage!A:G,7,0) -> 163 | L27: =VLOOKUP(D27,Coverage!A:H,8,0) -> 2.2328767 | M27: =VLOOKUP(D27,Coverage!A:I,9,0) -> 27 | N27: =M27/F27 -> 0.35064935
A28: Diab III | B28: 1-Jan-2024 | C28: 998 | D28: Shereen Tarek Gouda El-Sayed | E28: DIAB-III P. SAID-N. SINAI | F28: =VLOOKUP(D28,Coverage!A:B,2,0) -> 66 | G28: =VLOOKUP(D28,Coverage!A:C,3,0) -> 61 | H28: =VLOOKUP(D28,Coverage!A:D,4,0) -> 0.92424242 | I28: =VLOOKUP(D28,Coverage!A:E,5,0) -> 5 | J28: =VLOOKUP(D28,Coverage!A:F,6,0) -> 62 | K28: =VLOOKUP(D28,Coverage!A:G,7,0) -> 150 | L28: =VLOOKUP(D28,Coverage!A:H,8,0) -> 2.4193548 | M28: =VLOOKUP(D28,Coverage!A:I,9,0) -> 19 | N28: =M28/F28 -> 0.28787879
A29: Diab III | D29: Vacant_Delta 1 | E29: DIAB-III DM DELTA A | F29: =SUM(F21,F24:F25,F27:F28) -> 415 | G29: =SUM(G21,G24:G25,G27:G28) -> 388 | H29: =G29/F29 -> 0.93493976 | I29: =SUM(I21,I24:I25,I27:I28) -> 27 | J29: =SUM(J21,J24:J25,J27:J28) -> 390 | K29: =SUM(K21,K24:K25,K27:K28) -> 757 | L29: =AVERAGE(L21,L24:L25,L27:L28) -> 1.9722023 | M29: =SUM(M21,M24:M25,M27:M28) -> 214 | N29: =M29/F29 -> 0.51566265
A30: Diab III | B30: 46023 | C30: 1992 | D30: Mostafa Mahmoud Gaber ElHajjar | E30: DIAB-III MENOFYA-A | F30: =VLOOKUP(D30,Coverage!A:B,2,0) -> 78 | G30: =VLOOKUP(D30,Coverage!A:C,3,0) -> 68 | H30: =VLOOKUP(D30,Coverage!A:D,4,0) -> 0.87179487 | I30: =VLOOKUP(D30,Coverage!A:E,5,0) -> 10 | J30: =VLOOKUP(D30,Coverage!A:F,6,0) -> 81 | K30: =VLOOKUP(D30,Coverage!A:G,7,0) -> 162 | L30: =VLOOKUP(D30,Coverage!A:H,8,0) -> 2 | M30: =VLOOKUP(D30,Coverage!A:I,9,0) -> 38 | N30: =M30/F30 -> 0.48717949
A31: Diab III | B31: 46023 | C31: 1995 | D31: Zeinab Serry AbdelSamie Ammar | E31: DIAB-III MENOFYA-B | F31: =VLOOKUP(D31,Coverage!A:B,2,0) -> 72 | G31: =VLOOKUP(D31,Coverage!A:C,3,0) -> 66 | H31: =VLOOKUP(D31,Coverage!A:D,4,0) -> 0.91666667 | I31: =VLOOKUP(D31,Coverage!A:E,5,0) -> 6 | J31: =VLOOKUP(D31,Coverage!A:F,6,0) -> 78 | K31: =VLOOKUP(D31,Coverage!A:G,7,0) -> 155 | L31: =VLOOKUP(D31,Coverage!A:H,8,0) -> 1.9871795 | M31: =VLOOKUP(D31,Coverage!A:I,9,0) -> 48 | N31: =M31/F31 -> 0.66666667
A32: Diab III | B32: 46023 | C32: 1994 | D32: Mariam AbuElMagd Ibrahim Abdullah ElNaggar | E32: DIAB-III GHARBIA-B | F32: =VLOOKUP(D32,Coverage!A:B,2,0) -> 96 | G32: =VLOOKUP(D32,Coverage!A:C,3,0) -> 69 | H32: =VLOOKUP(D32,Coverage!A:D,4,0) -> 0.71875 | I32: =VLOOKUP(D32,Coverage!A:E,5,0) -> 27 | J32: =VLOOKUP(D32,Coverage!A:F,6,0) -> 75 | K32: =VLOOKUP(D32,Coverage!A:G,7,0) -> 139 | L32: =VLOOKUP(D32,Coverage!A:H,8,0) -> 1.8533333 | M32: =VLOOKUP(D32,Coverage!A:I,9,0) -> 38 | N32: =M32/F32 -> 0.39583333
A33: Diab III | D33: Vacant_Gharbia_II | E33: DIAB-III GHARBIA-C | F33: =VLOOKUP(D33,Coverage!A:B,2,0) -> #N/A | G33: =VLOOKUP(D33,Coverage!A:C,3,0) -> #N/A | H33: =VLOOKUP(D33,Coverage!A:D,4,0) -> #N/A | I33: =VLOOKUP(D33,Coverage!A:E,5,0) -> #N/A | J33: =VLOOKUP(D33,Coverage!A:F,6,0) -> #N/A | K33: =VLOOKUP(D33,Coverage!A:G,7,0) -> #N/A | L33: =VLOOKUP(D33,Coverage!A:H,8,0) -> #N/A | M33: =VLOOKUP(D33,Coverage!A:I,9,0) -> #N/A | N33: =M33/F33 -> #N/A
A34: Diab III | B34: 46023 | C34: 1993 | D34: Mohamed Ahmed ElSayed Ahmed ElTaras | E34: DIAB-III GHARBIA-A | F34: =VLOOKUP(D34,Coverage!A:B,2,0) -> 90 | G34: =VLOOKUP(D34,Coverage!A:C,3,0) -> 53 | H34: =VLOOKUP(D34,Coverage!A:D,4,0) -> 0.58888889 | I34: =VLOOKUP(D34,Coverage!A:E,5,0) -> 37 | J34: =VLOOKUP(D34,Coverage!A:F,6,0) -> 86 | K34: =VLOOKUP(D34,Coverage!A:G,7,0) -> 141 | L34: =VLOOKUP(D34,Coverage!A:H,8,0) -> 1.6395349 | M34: =VLOOKUP(D34,Coverage!A:I,9,0) -> 20 | N34: =M34/F34 -> 0.22222222
A35: Diab III | B35: 46054 | C35: 2133 | D35: Hazem Mohamed HasaBallah Esmail Ibrahim | E35: DIAB-III KAFR ELSHEIKH-A | F35: =VLOOKUP(D35,Coverage!A:B,2,0) -> 71 | G35: =VLOOKUP(D35,Coverage!A:C,3,0) -> 31 | H35: =VLOOKUP(D35,Coverage!A:D,4,0) -> 0.43661972 | I35: =VLOOKUP(D35,Coverage!A:E,5,0) -> 40 | J35: =VLOOKUP(D35,Coverage!A:F,6,0) -> 36 | K35: =VLOOKUP(D35,Coverage!A:G,7,0) -> 40 | L35: =VLOOKUP(D35,Coverage!A:H,8,0) -> 1.1111111 | M35: =VLOOKUP(D35,Coverage!A:I,9,0) -> 6 | N35: =M35/F35 -> 0.084507042
A36: Diab III | B36: 2-Nov-2023 | C36: 940 | D36: Mohamed Mohamed Mohamed Hassan Salah | E36: DIAB-III KAFR ELSHEIKH-B | F36: =VLOOKUP(D36,Coverage!A:B,2,0) -> 79 | G36: =VLOOKUP(D36,Coverage!A:C,3,0) -> 70 | H36: =VLOOKUP(D36,Coverage!A:D,4,0) -> 0.88607595 | I36: =VLOOKUP(D36,Coverage!A:E,5,0) -> 9 | J36: =VLOOKUP(D36,Coverage!A:F,6,0) -> 72 | K36: =VLOOKUP(D36,Coverage!A:G,7,0) -> 147 | L36: =VLOOKUP(D36,Coverage!A:H,8,0) -> 2.0416667 | M36: =VLOOKUP(D36,Coverage!A:I,9,0) -> 25 | N36: =M36/F36 -> 0.3164557
A37: Diab III | B37: 44703 | C37: 576 | D37: Mohamed ElSayed Mostafa Gaber | E37: DIAB-III DM DELTA B | F37: =SUM(F36) -> 79 | G37: =SUM(G36) -> 70 | H37: =G37/F37 -> 0.88607595 | I37: =SUM(I36) -> 9 | J37: =SUM(J36) -> 72 | K37: =SUM(K36) -> 147 | L37: =AVERAGE(L36) -> 2.0416667 | M37: =SUM(M36) -> 25 | N37: =M37/F37 -> 0.3164557
A38: Diab III | B38: 46032 | C38: 2024 | D38: Ereny Awny Fouad Ibrahim Beshara | E38: DIAB-III ALEX EAST-A | F38: =VLOOKUP(D38,Coverage!A:B,2,0) -> 76 | G38: =VLOOKUP(D38,Coverage!A:C,3,0) -> 72 | H38: =VLOOKUP(D38,Coverage!A:D,4,0) -> 0.94736842 | I38: =VLOOKUP(D38,Coverage!A:E,5,0) -> 4 | J38: =VLOOKUP(D38,Coverage!A:F,6,0) -> 73 | K38: =VLOOKUP(D38,Coverage!A:G,7,0) -> 163 | L38: =VLOOKUP(D38,Coverage!A:H,8,0) -> 2.2328767 | M38: =VLOOKUP(D38,Coverage!A:I,9,0) -> 63 | N38: =M38/F38 -> 0.82894737
A39: Diab III | B39: 12-Apr-2025 | C39: 1587 | D39: Rana Mohamed Gaber AbdelHamid | E39: DIAB-III ALEX EAST-B | F39: =VLOOKUP(D39,Coverage!A:B,2,0) -> 67 | G39: =VLOOKUP(D39,Coverage!A:C,3,0) -> 66 | H39: =VLOOKUP(D39,Coverage!A:D,4,0) -> 0.98507463 | I39: =VLOOKUP(D39,Coverage!A:E,5,0) -> 1 | J39: =VLOOKUP(D39,Coverage!A:F,6,0) -> 67 | K39: =VLOOKUP(D39,Coverage!A:G,7,0) -> 129 | L39: =VLOOKUP(D39,Coverage!A:H,8,0) -> 1.9253731 | M39: =VLOOKUP(D39,Coverage!A:I,9,0) -> 64 | N39: =M39/F39 -> 0.95522388
A40: Diab III | B40: 46023 | C40: 2023 | D40: Mohamed Hussein AbdelNaiem Ahmed AbdelNaiem | E40: DIAB-III ALEX WEST | F40: =VLOOKUP(D40,Coverage!A:B,2,0) -> 68 | G40: =VLOOKUP(D40,Coverage!A:C,3,0) -> 59 | H40: =VLOOKUP(D40,Coverage!A:D,4,0) -> 0.86764706 | I40: =VLOOKUP(D40,Coverage!A:E,5,0) -> 9 | J40: =VLOOKUP(D40,Coverage!A:F,6,0) -> 60 | K40: =VLOOKUP(D40,Coverage!A:G,7,0) -> 120 | L40: =VLOOKUP(D40,Coverage!A:H,8,0) -> 2 | M40: =VLOOKUP(D40,Coverage!A:I,9,0) -> 43 | N40: =M40/F40 -> 0.63235294
A41: Diab III | B41: 16-Aug-2025 | C41: 1757 | D41: Ingy Mahmoud Mohamed Ahmed ElSheikh | E41: DIAB-III ALEX CENTER-B | F41: =VLOOKUP(D41,Coverage!A:B,2,0) -> 70 | G41: =VLOOKUP(D41,Coverage!A:C,3,0) -> 66 | H41: =VLOOKUP(D41,Coverage!A:D,4,0) -> 0.94285714 | I41: =VLOOKUP(D41,Coverage!A:E,5,0) -> 4 | J41: =VLOOKUP(D41,Coverage!A:F,6,0) -> 66 | K41: =VLOOKUP(D41,Coverage!A:G,7,0) -> 122 | L41: =VLOOKUP(D41,Coverage!A:H,8,0) -> 1.8484848 | M41: =VLOOKUP(D41,Coverage!A:I,9,0) -> 56 | N41: =M41/F41 -> 0.8
...

Sheet Coverage
B1: Target Customers | C1: Target Customers Visited | D1: Target Customers Visit Coverage % | E1: Not Covered Customers | F1: Visited Customers | G1: Actual Visits | H1: Visits per Customer | I1: Fully Covered Customers
A2: AbdelMoneim Sayed AbdelMoneim Sayed Darwish | B2: 79 | C2: 76 | D2: 0.96202532 | E2: 3 | F2: 76 | G2: 169 | H2: 2.2236842 | I2: 63
A3: Ahmed Adel Hosny Hassan | B3: 49 | C3: 14 | D3: 0.28571429 | E3: 35 | F3: 26 | G3: 27 | H3: 1.0384615 | I3: 14
A4: Alaa Aly Aly Abu El-Enein | B4: 87 | C4: 86 | D4: 0.98850575 | E4: 1 | F4: 87 | G4: 158 | H4: 1.816092 | I4: 56
A5: Amany Youssef Ismail Aly | B5: 91 | C5: 83 | D5: 0.91208791 | E5: 8 | F5: 83 | G5: 157 | H5: 1.8915663 | I5: 47
A6: Amin Ibrahim Mohamed Amin | B6: 77 | C6: 5 | D6: 0.064935065 | E6: 72 | F6: 6 | G6: 6 | H6: 1 | I6: 0
A7: Anas Mohamed ElSayed Ibrahim Salem | B7: 83 | C7: 66 | D7: 0.79518072 | E7: 17 | F7: 82 | G7: 131 | H7: 1.597561 | I7: 31
A8: Asmaa ElBel Zanaty Hussein Aly | B8: 95 | C8: 78 | D8: 0.82105263 | E8: 17 | F8: 78 | G8: 131 | H8: 1.6794872 | I8: 24
A9: Aya Aref Hussein AbdelHalim | B9: 82 | C9: 0 | D9: 0 | E9: 82 | F9: 0 | G9: 0 | H9: 0 | I9: 0
A10: Aya Mohamed Salah AbuElLail | B10: 91 | C10: 71 | D10: 0.78021978 | E10: 20 | F10: 71 | G10: 122 | H10: 1.7183099 | I10: 37
A11: Donia Mahmoud Mohamed Ahmed Mowafy | B11: 76 | C11: 76 | D11: 1 | E11: 0 | F11: 76 | G11: 169 | H11: 2.2236842 | I11: 69
A12: Eman Hamdy Shahat Esmail | B12: 73 | C12: 71 | D12: 0.97260274 | E12: 2 | F12: 71 | G12: 144 | H12: 2.028169 | I12: 39
A13: Ereen Maher Botros Abdullah | B13: 103 | C13: 97 | D13: 0.94174757 | E13: 6 | F13: 97 | G13: 172 | H13: 1.7731959 | I13: 52
... A57: Zeinab Serry AbdelSamie Ammar | B57: 72 | C57: 66 | D57: 0.91666667 | E57: 6 | F57: 78 | G57: 155 | H57: 1.9871795 | I57: 48
B58: 3968 | C58: 3234 | D58: 0.81502016 | E58: 938 | F58: 3386 | G58: 6658 | H58: 1.966332 | I58: 2076
