Workbook
Name performance1: Performance!$A:$P

Sheet Till 16 - Oct
A1: Hiring Date | B1: Code | C1: Name | D1: Area | E1: Calendar Days | F1: Holidays | G1: Leave Days | H1: Activity Days | I1: NFA Days (Leave&Activity) | J1: Supposed Visit Days | K1: Actual Visit Days | L1: Missing Work Days | M1: Target Visits | N1: Target Visits Done | O1: Target Visits Achievement % | P1: Average Daily Visits (Actual Visit Days) | Q1: Calls per Visit | R1: Average Visit Duration | S1: Actual Visits | T1: Daily Target Visits 2025 | U1: Visits out of Target List
A3: 12-Jul-2025 | B3: 1707 | C3: AbdelMoneim Sayed AbdelMoneim Sayed Darwish | D3: Cairoeast_I - ElKobba - Elabbasia | E3: 16 | F3: 0 | G3: 0 | H3: 0 | I3: 0 | J3: 11 | K3: 10 | L3: 1 | M3: 139 | N3: 76 | O3: 0.54676259 | P3: 8.5 | Q3: 0 | R3: 3.8578431 | S3: 85 | T3: 9 | U3: 9
A4: 22-Jun-2024 | B4: 1188 | C4: Mahmoud Mohamed Abdelmahdy Abdullah | D4: Cairoeast_II | E4: 16 | F4: 0 | G4: 0 | H4: 0 | I4: 0 | J4: 11 | K4: 9 | L4: 2 | M4: 196 | N4: 76 | O4: 0.3877551 | P4: 8.8888889 | Q4: 0.875 | R4: 7.6460417 | S4: 80 | T4: 9 | U4: 4
A5: 1-Dec-2024 | B5: 1331 | C5: Yasmin Sayed AbdelLatif Mohamed Hekal | D5: Cairoeast_III | E5: 16 | F5: 0 | G5: 0 | H5: 0 | I5: 0 | J5: 11 | K5: 5 | L5: 6 | M5: 142 | N5: 50 | O5: 0.35211268 | P5: 10.2 | Q5: 1.9803922 | R5: 5.598366 | S5: 51 | T5: 8 | U5: 1
A6: 1-Jan-2024 | B6: 960 | C6: Hoda Abdel Tawab Ismail El-Dib | D6: Heliopolis_I - Heliopolis_II | E6: 16 | F6: 0 | G6: 0 | H6: 0 | I6: 0 | J6: 11 | K6: 8 | L6: 3 | M6: 166 | N6: 52 | O6: 0.31325301 | P6: 6.875 | Q6: 0 | R6: 9.0387879 | S6: 55 | T6: 8 | U6: 3
A7: 7-Sept-2024 | B7: 1268 | C7: Mariam Makram Ragheb Soliman | D7: Heliopolis_III | E7: 16 | F7: 0 | G7: 0 | H7: 0 | I7: 0 | J7: 11 | K7: 9 | L7: 2 | M7: 153 | N7: 61 | O7: 0.39869281 | P7: 6.7777778 | Q7: 0 | R7: 23.828415 | S7: 61 | T7: 7 | U7: 0
A8: 3-Mar-2021 | B8: 333 | C8: May Ibrahim Mohamed Abdel Wahab Soliman | D8: NasrCity | E8: 16 | F8: 0 | G8: 0 | H8: 0 | I8: 0 | J8: 11 | K8: 8 | L8: 3 | M8: 147 | N8: 51 | O8: 0.34693878 | P8: 6.875 | Q8: 1 | R8: 4.9654545 | S8: 55 | T8: 8 | U8: 4
A9: 1-Jan-2024 | B9: 1006 | C9: Kholoud El-Matarawy Mohamed Aly | D9: New Cairo_Rehab | E9: 16 | F9: 0 | G9: 0 | H9: 0 | I9: 0 | J9: 11 | K9: 10 | L9: 1 | M9: 154 | N9: 71 | O9: 0.46103896 | P9: 7.5 | Q9: 0 | R9: 10.142444 | S9: 75 | T9: 8 | U9: 4
A10: 10-Aug-2024 | B10: 1246 | C10: Mayar Mahmoud Mohamed AbdelHafez | D10: Ismailia - Suez/S.Sinai | E10: 16 | F10: 0 | G10: 0 | H10: 0 | I10: 0 | J10: 11 | K10: 10 | L10: 1 | M10: 179 | N10: 79 | O10: 0.44134078 | P10: 8.7777778 | Q10: 0 | R10: 15.875105 | S10: 79 | T10: 9 | U10: 0
A11: 1-Feb-2025 | B11: 1439 | C11: Peter AbdelNasser Fathy Habel | D11: Cairo 1 | E11: 16 | F11: 0 | G11: 0 | H11: 0 | I11: 0 | J11: 11 | K11: 6 | L11: 5 | M11: 1137 | N11: 440 | O11: 0.38698329 | P11: 7.9849206 | Q11: 0.55077031 | R11: 11.013516 | S11: 456
A12: 2-Apr-2022 | B12: 543 | C12: Amira Essam Ahmed Ahmed | D12: Shoubraelkhima | E12: 16 | F12: 0 | G12: 0.5 | H12: 0 | I12: 0.5 | J12: 10.5 | K12: 10 | L12: 0.5 | M12: 170 | N12: 71 | O12: 0.41764706 | P12: 7.2 | Q12: 0 | R12: 11.996759 | S12: 72 | T12: 8 | U12: 1
A13: 1-Jan-2024 | B13: 962 | C13: Nada Refaat Mohamed Ahmed | D13: CairoWest_I - CairoWest_II - CairoWest_III | E13: 16 | F13: 0 | G13: 0 | H13: 2 | I13: 2 | J13: 9 | K13: 8 | L13: 1 | M13: 154 | N13: 53 | O13: 0.34415584 | P13: 6.75 | Q13: 0 | R13: 14.345062 | S13: 54 | T13: 8 | U13: 1
A14: 17-Aug-2025 | B14: 1765 | C14: Rabab SalahElDin Ragab AbdelRahman | D14: CairoCenter - Cairosouth_I | E14: 16 | F14: 0 | G14: 0 | H14: 1 | I14: 1 | J14: 10 | K14: 10 | L14: 0 | M14: 119 | N14: 47 | O14: 0.39495798 | P14: 5.1 | Q14: 0 | R14: 11.113072 | S14: 51 | T14: 6 | U14: 4
A15: 5-Apr-2025 | B15: 1583 | C15: Nada Anwar Ahmed Mousa | D15: CairoSouth_II - CairoSouth_III | E15: 16 | F15: 0 | G15: 0 | H15: 1 | I15: 1 | J15: 10 | K15: 8 | L15: 2 | M15: 208 | N15: 76 | O15: 0.36538462 | P15: 9.875 | Q15: 0 | R15: 8.471519 | S15: 79 | T15: 8 | U15: 3
A16: 29-Aug-2020 | B16: 230 | C16: Nourhan Ashraf Mostafa Hassan | D16: Maadi | E16: 16 | F16: 0 | G16: 5 | H16: 0 | I16: 5 | J16: 6 | K16: 6 | L16: 0 | M16: 108 | N16: 28 | O16: 0.25925926 | P16: 4.8333333 | Q16: 0 | R16: 13.960345 | S16: 29 | T16: 5 | U16: 1
A17: 1-Jan-2024 | B17: 964 | C17: Amira Ateya Fawzy Ateya | D17: Helwan | E17: 16 | F17: 0 | G17: 0 | H17: 1 | I17: 1 | J17: 10 | K17: 10 | L17: 0 | M17: 166 | N17: 79 | O17: 0.47590361 | P17: 8 | Q17: 1.825 | R17: 8.72875 | S17: 80 | T17: 8 | U17: 1
A18: 1-Jan-2024 | B18: 967 | C18: Ahmed Mostafa Hamza Mohamed | D18: Kalubeia_I - Kalubeia_II | E18: 16 | F18: 0 | G18: 0 | H18: 1 | I18: 1 | J18: 10 | K18: 8 | L18: 2 | M18: 135 | N18: 72 | O18: 0.53333333 | P18: 9 | Q18: 0 | R18: 15.946065 | S18: 72 | T18: 8 | U18: 0
A19: 17-Oct-2020 | B19: 240 | C19: Mohamed AbdelAziz Mohamed Abdel Latif El-Tahlawy | D19: Cairo 2 | E19: 16 | F19: 0 | G19: 0 | H19: 0 | I19: 0 | J19: 11 | K19: 6 | L19: 5 | M19: 787 | N19: 326 | O19: 0.41423126 | P19: 7.7816667 | Q19: 0.365 | R19: 11.820688 | S19: 332 | T19: 0
A20: 10-Aug-2024 | B20: 1248 | C20: Mariam AbdelRahman Abdel Samie Abdel Wadod | D20: Sharkia_I | E20: 16 | F20: 0 | G20: 1 | H20: 0 | I20: 1 | J20: 10 | K20: 9 | L20: 1 | M20: 189 | N20: 79 | O20: 0.41798942 | P20: 8.8888889 | Q20: 1.675 | R20: 20.086042 | S20: 80 | T20: 9 | U20: 1
A21: 5-Jul-2025 | B21: 1701 | C21: Rania Mohsen Ahmed Mohamed | D21: Sharkia_II | E21: 16 | F21: 0 | G21: 0 | H21: 0 | I21: 0 | J21: 11 | K21: 9 | L21: 2 | M21: 192 | N21: 82 | O21: 0.42708333 | P21: 9.3333333 | Q21: 0.035714286 | R21: 14.421429 | S21: 84 | T21: 10 | U21: 2
A22: 4-Feb-2024 | B22: 1061 | C22: Hoda Aly Mostafa Ahmed Mohamed | D22: Sharkia_III | E22: 16 | F22: 0 | G22: 6 | H22: 0 | I22: 6 | J22: 5 | K22: 5 | L22: 0 | M22: 207 | N22: 50 | O22: 0.24154589 | P22: 10 | Q22: 1.84 | R22: 16.872667 | S22: 50 | T22: 10 | U22: 0
A23: 1-Jan-2024 | B23: 1047 | C23: Alaa Aly Aly Abu El-Enein | D23: Dakahleia_I - Dakahleia_IV | E23: 16 | F23: 0 | G23: 1 | H23: 0 | I23: 1 | J23: 10 | K23: 8 | L23: 2 | M23: 168 | N23: 72 | O23: 0.42857143 | P23: 9 | Q23: 0 | R23: 18.15625 | S23: 72 | T23: 8 | U23: 0
A24: 14-Mar-2024 | B24: 1117 | C24: Reem Hassan Tolba Ibrahim | D24: Dakahleia_II | E24: 16 | F24: 0 | G24: 0 | H24: 0 | I24: 0 | J24: 11 | K24: 10 | L24: 1 | M24: 175 | N24: 71 | O24: 0.40571429 | P24: 7.4 | Q24: 1.472973 | R24: 24.176802 | S24: 74 | T24: 9 | U24: 3
A25: 27-Feb-2021 | B25: 311 | C25: Ghada Samir Mohamed Mohamed | D25: Dakahleia_III | E25: 16 | F25: 0 | G25: 1 | H25: 0 | I25: 1 | J25: 10 | K25: 9 | L25: 1 | M25: 212 | N25: 76 | O25: 0.35849057 | P25: 8.4444444 | Q25: 0 | R25: 12.364035 | S25: 76 | T25: 10 | U25: 0
A26: 18-Jul-2020 | B26: 194 | C26: Menna Allah Hassouna Abbas Hassouna | D26: Domiat | E26: 16 | F26: 0 | G26: 0.5 | H26: 0 | I26: 0.5 | J26: 10.5 | K26: 10 | L26: 0.5 | M26: 183 | N26: 77 | O26: 0.42076503 | P26: 8.5555556 | Q26: 0 | R26: 21.511688 | S26: 77 | T26: 10 | U26: 0
A27: 1-Jan-2024 | B27: 998 | C27: Shereen Tarek Gouda El-Sayed | D27: PortSaid/N.Sinai | E27: 16 | F27: 0 | G27: 5 | H27: 0 | I27: 5 | J27: 6 | K27: 5 | L27: 1 | M27: 189 | N27: 38 | O27: 0.2010582 | P27: 8.2 | Q27: 0 | R27: 10.445122 | S27: 41 | T27: 9 | U27: 3
A28: 1-Jan-2024 | B28: 973 | C28: Mina Magdy Zekry Metry | D28: Delta 1 | E28: 16 | F28: 0 | G28: 0 | H28: 0 | I28: 0 | J28: 11 | K28: 6 | L28: 5 | M28: 1323 | N28: 463 | O28: 0.34996221 | P28: 8.6412698 | Q28: 0.71256757 | R28: 17.658944 | S28: 470 | T28: 0
A29: 1-Jan-2024 | B29: 1008 | C29: Hagar Abdel Aziz Ahmed Qamh | D29: Menofeya_I - Menofeya_II | E29: 16 | F29: 0 | G29: 0 | H29: 0 | I29: 0 | J29: 11 | K29: 11 | L29: 0 | M29: 177 | N29: 72 | O29: 0.40677966 | P29: 6.8181818 | Q29: 1.9066667 | R29: 21.782667 | S29: 75 | T29: 8 | U29: 3
A30: 1-Jan-2024 | B30: 999 | C30: Mohamed Sobhy Afifi Mazied | D30: Menofeya_III | E30: 16 | F30: 0 | G30: 0 | H30: 0 | I30: 0 | J30: 11 | K30: 11 | L30: 0 | M30: 155 | N30: 80 | O30: 0.51612903 | P30: 7.7272727 | Q30: 1.8352941 | R30: 4.7570588 | S30: 85 | T30: 10 | U30: 5
A31: 21-May-2022 | B31: 576 | C31: Mohamed El-Sayed Mostafa Gaber | D31: Gharbia_I | E31: 16 | F31: 0 | G31: 0 | H31: 0 | I31: 0 | J31: 11 | K31: 10 | L31: 1 | M31: 156 | N31: 71 | O31: 0.45512821 | P31: 7.1 | Q31: 0 | R31: 3.8826291 | S31: 71 | T31: 8 | U31: 0
A32: 1-Jan-2024 | B32: 1002 | C32: Omar Mohamed Abdel Hamid Megahed El-Samahy | D32: Gharbia_II | E32: 16 | F32: 0 | G32: 0 | H32: 0 | I32: 0 | J32: 11 | K32: 9 | L32: 2 | M32: 179 | N32: 62 | O32: 0.34636872 | P32: 7.4444444 | Q32: 1.7014925 | R32: 27.318657 | S32: 67 | T32: 9 | U32: 5
A33: 31-Jul-2025 | B33: 1721 | C33: kyrilles AbdElmalek Gorgy AbdElmalek Boghdady | D33: Gharbia_III | E33: 16 | F33: 0 | G33: 0 | H33: 0 | I33: 0 | J33: 11 | K33: 11 | L33: 0 | M33: 168 | N33: 85 | O33: 0.50595238 | P33: 7.7272727 | Q33: 0 | R33: 3.0952941 | S33: 85 | T33: 8 | U33: 0
A34: 1-Jan-2024 | B34: 1003 | C34: Reham Ateya Mohamed Ibrahim Nasr | D34: Kafrelsheikh_I | E34: 16 | F34: 0 | G34: 0 | H34: 0 | I34: 0 | J34: 11 | K34: 9 | L34: 2 | M34: 157 | N34: 70 | O34: 0.44585987 | P34: 8.5555556 | Q34: 0 | R34: 7.2751082 | S34: 77 | T34: 9 | U34: 7
A35: 2-Nov-2023 | B35: 940 | C35: Mohamed Mohamed Mohamed Hassan Salah | D35: Kafrelsheikh_II | E35: 16 | F35: 0 | G35: 0 | H35: 0 | I35: 0 | J35: 11 | K35: 10 | L35: 1 | M35: 218 | N35: 79 | O35: 0.36238532 | P35: 8.3 | Q35: 0 | R35: 13.613655 | S35: 83 | T35: 10 | U35: 4
A36: 1-Jan-2024 | B36: 981 | C36: Ola Aly Abdel Fatah El-Rayis | D36: Delta 2 | E36: 16 | F36: 0 | G36: 0 | H36: 0 | I36: 0 | J36: 11 | K36: 2 | L36: 9 | M36: 1042 | N36: 434 | O36: 0.41650672 | P36: 7.6575758 | Q36: 0.90724222 | R36: 13.104962 | S36: 458 | T36: 0
A37: 1-Dec-2024 | B37: 1334 | C37: Mirrete Refaat GabAllah AttaAllah Abdo | D37: Alexeast_I - Alexeast_II | E37: 16 | F37: 0 | G37: 0 | H37: 0.5 | I37: 0.5 | J37: 10.5 | K37: 10 | L37: 0.5 | M37: 149 | N37: 84 | O37: 0.56375839 | P37: 8.5 | Q37: 1.0941176 | R37: 15.027059 | S37: 85 | T37: 8 | U37: 1
A38: 12-Apr-2025 | B38: 1587 | C38: Rana Mohamed Gaber AbdelHamid | D38: Alexeast_III | E38: 16 | F38: 0 | G38: 0 | H38: 0 | I38: 0 | J38: 11 | K38: 10 | L38: 1 | M38: 159 | N38: 69 | O38: 0.43396226 | P38: 6.9 | Q38: 0.94202899 | R38: 14.483816 | S38: 69 | T38: 7 | U38: 0
A39: 1-Jan-2024 | B39: 971 | C39: Israa Samir Gaber Mohamed Ateya | D39: Alexcenter_I / Alex_west_I | E39: 16 | F39: 0 | G39: 0 | H39: 0 | I39: 0 | J39: 11 | K39: 10 | L39: 1 | M39: 131 | N39: 65 | O39: 0.49618321 | P39: 6.5 | Q39: 0.030769231 | R39: 39.598205 | S39: 65 | T39: 7 | U39: 0
A40: 16-Aug-2025 | B40: 1757 | C40: Ingy Mahmoud Mohamed Ahmed ElSheikh | D40: Alexcenter_II | E40: 16 | F40: 0 | G40: 0 | H40: 0.5 | I40: 0.5 | J40: 10.5 | K40: 11 | L40: 0 | M40: 159 | N40: 78 | O40: 0.49056604 | P40: 7.0909091 | Q40: 1.7051282 | R40: 16.131624 | S40: 78 | T40: 7 | U40: 0
A41: 1-Jan-2024 | B41: 1000 | C41: kyrilles Ateya Milad Ateya Gayed | D41: Alex_west II/Matrouh | E41: 16 | F41: 0 | G41: 3 | H41: 1 | I41: 4 | J41: 7 | K41: 7 | L41: 0 | M41: 140 | N41: 69 | O41: 0.49285714 | P41: 10.142857 | Q41: 0 | R41: 4.6279343 | S41: 71 | T41: 9 | U41: 2
...

Sheet 2-2026
A1: Line | B1: Hiring Date | C1: Code | D1: Name | E1: Area | F1: Calendar Days | G1: Holidays | H1: Leave Days | I1: Activity Days | J1: NFA Days (Leave&Activity) | K1: Supposed Visit Days | L1: All Visit Days | M1: Missing Work Days | N1: Target Visits | O1: Target Visits Done | P1: Target Visits Achievement % | Q1: Average Daily Visits (Actual Visit Days) | R1: Calls per Visit | S1: Average Visit Duration | T1: Actual Visits | U1: Daily Target Visits 2025 | V1: Visits out of Target List
A3: Diab III | B3: 12-Jul-2025 | C3: 1707 | D3: AbdelMoneim Sayed AbdelMoneim Sayed Darwish | E3: DIAB-III ABBASEIA-KOBBAH | F3: 28 | G3: 0 | H3: 1 | I3: 2 | J3: 3 | K3: 17 | L3: 18 | M3: 0 | N3: 173 | O3: 169 | P3: 0.97687861 | Q3: 9.9411765 | R3: 0 | S3: 3.462426 | T3: 169 | V3: 0
A4: Diab III | B4: 22-Jun-2024 | C4: 1188 | D4: Mahmoud Mohamed Abdelmahdy Abdullah | E4: DIAB-III CAIRO EAST | F4: 28 | G4: 0 | H4: 3 | I4: 1.5 | J4: 4.5 | K4: 15.5 | L4: 16 | M4: 0 | N4: 176 | O4: 155 | P4: 0.88068182 | Q4: 10.387097 | R4: 0.01242236 | S4: 18.500725 | T4: 161 | V4: 6
A5: Diab III | B5: 1-Dec-2024 | C5: 1331 | D5: Yasmin Sayed AbdelLatif Mohamed Hekal | E5: DIAB-III AIN SHAMS | F5: 28 | G5: 0 | H5: 1 | I5: 1.5 | J5: 2.5 | K5: 17.5 | L5: 18 | M5: 0 | N5: 161 | O5: 158 | P5: 0.98136646 | Q5: 9.0285714 | R5: 1.9050633 | S5: 3.8904008 | T5: 158 | V5: 0
A6: Diab III | B6: 46025 | C6: 2008 | D6: Guirgis Samir Azmy Iskandar | E6: DIAB-III HELIOPOLIS-A | F6: 28 | G6: 0 | H6: 3 | I6: 1 | J6: 4 | K6: 16 | L6: 16 | M6: 0 | N6: 197 | O6: 123 | P6: 0.62436548 | Q6: 8.375 | R6: 0 | S6: 3.6572139 | T6: 134 | V6: 11
A7: Diab III | B7: 7-Sept-2024 | C7: 1268 | D7: Mariam Makram Ragheb Soliman | E7: DIAB-III HELIOPOLIS-B | F7: 28 | G7: 0 | H7: 2 | I7: 2 | J7: 4 | K7: 16 | L7: 17 | M7: 0 | N7: 191 | O7: 154 | P7: 0.80628272 | Q7: 9.625 | R7: 0 | S7: 7.3560606 | T7: 154 | V7: 0
A8: Diab III | D8: Vacant_NasrCity | E8: DIAB-III NASR CITY | F8: 0 | G8: 0 | H8: 0 | I8: 0 | J8: 0 | K8: 0 | L8: 0 | M8: 0 | N8: 0 | O8: 0 | P8: 0 | Q8: 0 | R8: 0 | S8: 0 | T8: 0 | V8: 0
A9: Diab III | B9: 1-Jan-2024 | C9: 1006 | D9: Kholoud El-Matarawy Mohamed Aly | E9: DIAB-III NEW CAIRO | F9: 28 | G9: 0 | H9: 2 | I9: 1 | J9: 3 | K9: 17 | L9: 17 | M9: 0 | N9: 177 | O9: 151 | P9: 0.85310734 | Q9: 9.0588235 | R9: 0 | S9: 13.199784 | T9: 154 | V9: 3
A10: Diab III | B10: 46032 | C10: 2007 | D10: Rania Helmy Lotfy Mohamed ElAsour | E10: DIAB-III ISMAILIA-SUIZ | F10: 28 | G10: 0 | H10: 2 | I10: 2 | J10: 4 | K10: 16 | L10: 10 | M10: 6 | N10: 214 | O10: 66 | P10: 0.30841121 | Q10: 4.125 | R10: 0 | S10: 3.3406566 | T10: 66 | V10: 0
A11: Diab III | B11: 1-Feb-2025 | C11: 1439 | D11: Peter AbdelNasser Fathy Habel | E11: DIAB-III DM CAIRO B | F11: 28 | G11: 0 | H11: 0 | I11: 0 | J11: 0 | K11: 20 | L11: 15 | M11: 5 | N11: 878 | O11: 787 | P11: 0.89635535 | Q11: 9.6081336 | R11: 0.38349713 | S11: 9.2818791 | T11: 36
A12: Diab III | D12: Vacant_Shoubraelkhemah | E12: DIAB-III SHOBRA EL KHEMAH | F12: 0 | G12: 0 | H12: 0 | I12: 0 | J12: 0 | K12: 0 | L12: 0 | M12: 0 | N12: 0 | O12: 0 | P12: 0 | Q12: 0 | R12: 0 | S12: 0 | T12: 0 | V12: 0
A13: Diab III | B13: 2-Nov-2025 | C13: 1839 | D13: Eman Hamdy Shahat Esmail | E13: DIAB-III CAIRO WEST | F13: 28 | G13: 0 | H13: 0 | I13: 1 | J13: 1 | K13: 19 | L13: 17 | M13: 2 | N13: 182 | O13: 144 | P13: 0.79120879 | Q13: 7.5789474 | R13: 0 | S13: 25.447106 | T13: 144 | V13: 0
A14: Diab III | B14: 46023 | C14: 2018 | D14: Mohamed Mostafa Mohamed Mahmoud Azzam | E14: DIAB-III CAIRO CENTER | F14: 28 | G14: 0 | H14: 1 | I14: 1.5 | J14: 2.5 | K14: 17.5 | L14: 16 | M14: 1.5 | N14: 158 | O14: 120 | P14: 0.75949367 | Q14: 6.8571429 | R14: 0 | S14: 12.007778 | T14: 120 | V14: 0
A15: Diab III | B15: 46032 | C15: 2074 | D15: Asmaa ElBel Zanaty Hussein Aly | E15: DIAB-III CAIRO SOUTH | F15: 28 | G15: 0 | H15: 0 | I15: 1 | J15: 1 | K15: 19 | L15: 17 | M15: 2 | N15: 253 | O15: 131 | P15: 0.51778656 | Q15: 6.8947368 | R15: 0 | S15: 16.027099 | T15: 131 | V15: 0
A16: Diab III | B16: 29-Aug-2020 | C16: 230 | D16: Nourhan Ashraf Mostafa Hassan | E16: DIAB-III MAADI | F16: 28 | G16: 0 | H16: 0 | I16: 0 | J16: 0 | K16: 20 | L16: 0 | M16: 20 | N16: 147 | O16: 0 | P16: 0 | Q16: 0 | R16: 0 | S16: 0 | T16: 0 | V16: 0
A17: Diab III | B17: 1-Jan-2024 | C17: 964 | D17: Fatma Fawzy Mohamed Mahmoud | E17: DIAB-III HELWAN | F17: 28 | G17: 0 | H17: 1 | I17: 1 | J17: 2 | K17: 18 | L17: 15 | M17: 3 | N17: 189 | O17: 127 | P17: 0.67195767 | Q17: 7.0555556 | R17: 0.015748031 | S17: 15.453018 | T17: 127 | V17: 0
A18: Diab III | B18: 46033 | C18: 2075 | D18: Maha Magdy AbdelSalam Mahmoud Farag | E18: DIAB-III QALUBIA-A | F18: 28 | G18: 0 | H18: 0 | I18: 1 | J18: 1 | K18: 19 | L18: 16 | M18: 3 | N18: 197 | O18: 163 | P18: 0.82741117 | Q18: 8.6315789 | R18: 0.32317073 | S18: 7.328252 | T18: 164 | V18: 1
A19: Diab III | B19: 46023 | C19: 2019 | D19: Mahmoud Lotfy Saied AbdelFatah | E19: DIAB-III QALUBIA-B | F19: 28 | G19: 0 | H19: 0 | I19: 0.5 | J19: 0.5 | K19: 19.5 | L19: 14 | M19: 5.5 | N19: 194 | O19: 146 | P19: 0.75257732 | Q19: 7.5384615 | R19: 0.97278912 | S19: 4.8744898 | T19: 147 | V19: 1
A20: Diab III | B20: 46023 | C20: 1902 | D20: Ahmed Adel Hosny Hassan | E20: DIAB-III DM CAIRO A | F20: 28 | G20: 0 | H20: 0 | I20: 0 | J20: 0 | K20: 20 | L20: 13 | M20: 7 | N20: 518 | O20: 271 | P20: 0.52316602 | Q20: 4.8781676 | R20: 0.0052493438 | S20: 13.633375 | T20: 271
A21: Diab III | B21: 10-Aug-2024 | C21: 1248 | D21: Mariam AbdelRahman Abdel Samie Abdel Wadod | E21: DIAB-III SHARKIA-A | F21: 28 | G21: 0 | H21: 0 | I21: 0 | J21: 0 | K21: 20 | L21: 17 | M21: 3 | N21: 216 | O21: 163 | P21: 0.75462963 | Q21: 8.15 | R21: 1.4969325 | S21: 20.248466 | T21: 163 | V21: 0
A22: Diab III | B22: 46023 | C22: 2020 | D22: Youssef AbdelBaset Esmail Ahmed Ammar Badran | E22: DIAB-III SHARKIA-B | F22: 28 | G22: 0 | H22: 0 | I22: 0 | J22: 0 | K22: 20 | L22: 18 | M22: 2 | N22: 215 | O22: 148 | P22: 0.68837209 | Q22: 7.8 | R22: 1.2692308 | S22: 17.218056 | T22: 156 | V22: 8
A23: Diab III | B23: 46032 | C23: 2039 | D23: Anas Mohamed ElSayed Ibrahim Salem | E23: DIAB-III SHARKIA-C | F23: 28 | G23: 0 | H23: 0 | I23: 0 | J23: 0 | K23: 20 | L23: 14 | M23: 6 | N23: 187 | O23: 110 | P23: 0.58823529 | Q23: 6.55 | R23: 1.9160305 | S23: 5.3447837 | T23: 131 | V23: 21
A24: Diab III | B24: 1-Jan-2024 | C24: 1047 | D24: Alaa Aly Aly Abu El-Enein | E24: DIAB-III DAKAHLIA-A | F24: 28 | G24: 0 | H24: 0 | I24: 0 | J24: 0 | K24: 20 | L24: 18 | M24: 2 | N24: 184 | O24: 157 | P24: 0.85326087 | Q24: 7.9 | R24: 0 | S24: 15.115084 | T24: 158 | V24: 1
A25: Diab III | B25: 14-Mar-2024 | C25: 1117 | D25: Reem Hassan Tolba Ibrahim | E25: DIAB-III DAKAHLIA-B | F25: 28 | G25: 0 | H25: 0 | I25: 0 | J25: 0 | K25: 20 | L25: 16 | M25: 4 | N25: 147 | O25: 123 | P25: 0.83673469 | Q25: 6.15 | R25: 1.8211382 | S25: 25.008401 | T25: 123 | V25: 0
A26: Diab III | B26: 46023 | C26: 2021 | D26: Donia Mahmoud Mohamed Ahmed Mowafy | E26: DIAB-III DAKAHLIA-C | F26: 28 | G26: 0 | H26: 0 | I26: 0 | J26: 0 | K26: 20 | L26: 18 | M26: 2 | N26: 156 | O26: 169 | P26: 1.0833333 | Q26: 8.45 | R26: 1.7692308 | S26: 5.2704142 | T26: 169 | V26: 0
A27: Diab III | B27: 18-Jul-2020 | C27: 194 | D27: Menna Allah Hassouna Abbas Hassouna | E27: DIAB-III DOMIAT | F27: 28 | G27: 0 | H27: 0 | I27: 0 | J27: 0 | K27: 20 | L27: 17 | M27: 3 | N27: 232 | O27: 163 | P27: 0.70258621 | Q27: 8.15 | R27: 0 | S27: 28.184969 | T27: 163 | V27: 0
A28: Diab III | B28: 1-Jan-2024 | C28: 998 | D28: Shereen Tarek Gouda El-Sayed | E28: DIAB-III P. SAID-N. SINAI | F28: 28 | G28: 0 | H28: 0 | I28: 0 | J28: 0 | K28: 20 | L28: 17 | M28: 3 | N28: 212 | O28: 148 | P28: 0.69811321 | Q28: 7.5 | R28: 0 | S28: 12.240222 | T28: 150 | V28: 2
A29: Diab III | D29: Vacant_Delta 1 | E29: DIAB-III DM DELTA A | F29: 28 | G29: 0 | H29: 0 | I29: 0 | J29: 0 | K29: 20 | L29: 0 | M29: 20 | N29: 775 | O29: 591 | P29: 0.76258065 | Q29: 7.425 | R29: 0.45528455 | S29: 20.137169 | T29: 594
A30: Diab III | B30: 46023 | C30: 1992 | D30: Mostafa Mahmoud Gaber ElHajjar | E30: DIAB-III MENOFYA-A | F30: 28 | G30: 0 | H30: 0 | I30: 1 | J30: 1 | K30: 19 | L30: 18 | M30: 1 | N30: 192 | O30: 141 | P30: 0.734375 | Q30: 8.5263158 | R30: 1.3641975 | S30: 11.561214 | T30: 162 | V30: 21
A31: Diab III | B31: 46023 | C31: 1995 | D31: Zeinab Serry AbdelSamie Ammar | E31: DIAB-III MENOFYA-B | F31: 28 | G31: 0 | H31: 1 | I31: 1 | J31: 2 | K31: 18 | L31: 17 | M31: 1 | N31: 159 | O31: 137 | P31: 0.86163522 | Q31: 8.6111111 | R31: 0 | S31: 12.290968 | T31: 155 | V31: 18
A32: Diab III | B32: 46023 | C32: 1994 | D32: Mariam AbuElMagd Ibrahim Abdullah ElNaggar | E32: DIAB-III GHARBIA-B | F32: 28 | G32: 0 | H32: 2 | I32: 1 | J32: 3 | K32: 17 | L32: 17 | M32: 0 | N32: 213 | O32: 132 | P32: 0.61971831 | Q32: 8.1764706 | R32: 1.0215827 | S32: 7.2068345 | T32: 139 | V32: 7
A33: Diab III | D33: Vacant_Gharbia_II | E33: DIAB-III GHARBIA-C | F33: 0 | G33: 0 | H33: 0 | I33: 0 | J33: 0 | K33: 0 | L33: 0 | M33: 0 | N33: 0 | O33: 0 | P33: 0 | Q33: 0 | R33: 0 | S33: 0 | T33: 0 | V33: 0
A34: Diab III | B34: 46023 | C34: 1993 | D34: Mohamed Ahmed ElSayed Ahmed ElTaras | E34: DIAB-III GHARBIA-A | F34: 28 | G34: 0 | H34: 1 | I34: 1 | J34: 2 | K34: 18 | L34: 18 | M34: 0 | N34: 198 | O34: 92 | P34: 0.46464646 | Q34: 7.8333333 | R34: 0 | S34: 5.1261229 | T34: 141 | V34: 49
A35: Diab III | B35: 46054 | C35: 2133 | D35: Hazem Mohamed HasaBallah Esmail Ibrahim | E35: DIAB-III KAFR ELSHEIKH-A | F35: 28 | G35: 0 | H35: 0 | I35: 0 | J35: 0 | K35: 20 | L35: 7 | M35: 13 | N35: 137 | O35: 35 | P35: 0.25547445 | Q35: 2 | R35: 0.5 | S35: 8.8504167 | T35: 40 | V35: 5
A36: Diab III | B36: 2-Nov-2023 | C36: 940 | D36: Mohamed Mohamed Mohamed Hassan Salah | E36: DIAB-III KAFR ELSHEIKH-B | F36: 28 | G36: 0 | H36: 0 | I36: 1.5 | J36: 1.5 | K36: 18.5 | L36: 18 | M36: 0.5 | N36: 224 | O36: 144 | P36: 0.64285714 | Q36: 7.9459459 | R36: 0 | S36: 11.71746 | T36: 147 | V36: 3
A37: Diab III | B37: 44703 | C37: 576 | D37: Mohamed ElSayed Mostafa Gaber | E37: DIAB-III DM DELTA B | F37: 28 | G37: 0 | H37: 0 | I37: 0 | J37: 0 | K37: 20 | L37: 11 | M37: 9 | N37: 224 | O37: 144 | P37: 0.64285714 | Q37: 7.9459459 | R37: 0 | S37: 11.71746 | T37: 147
A38: Diab III | B38: 46032 | C38: 2024 | D38: Ereny Awny Fouad Ibrahim Beshara | E38: DIAB-III ALEX EAST-A | F38: 28 | G38: 0 | H38: 1 | I38: 1.5 | J38: 2.5 | K38: 17.5 | L38: 18 | M38: 0 | N38: 161 | O38: 161 | P38: 1 | Q38: 9.3142857 | R38: 0.97546012 | S38: 10.494479 | T38: 163 | V38: 2
A39: Diab III | B39: 12-Apr-2025 | C39: 1587 | D39: Rana Mohamed Gaber AbdelHamid | E39: DIAB-III ALEX EAST-B | F39: 28 | G39: 0 | H39: 1 | I39: 1.5 | J39: 2.5 | K39: 17.5 | L39: 17 | M39: 0.5 | N39: 128 | O39: 128 | P39: 1 | Q39: 7.3714286 | R39: 1.0077519 | S39: 17.777261 | T39: 129 | V39: 1
A40: Diab III | B40: 46023 | C40: 2023 | D40: Mohamed Hussein AbdelNaiem Ahmed AbdelNaiem | E40: DIAB-III ALEX WEST | F40: 28 | G40: 0 | H40: 1 | I40: 2 | J40: 3 | K40: 17 | L40: 18 | M40: 0 | N40: 146 | O40: 119 | P40: 0.81506849 | Q40: 7.0588235 | R40: 1.9916667 | S40: 3.8288889 | T40: 120 | V40: 1
A41: Diab III | B41: 16-Aug-2025 | C41: 1757 | D41: Ingy Mahmoud Mohamed Ahmed ElSheikh | E41: DIAB-III ALEX CENTER-B | F41: 28 | G41: 0 | H41: 2 | I41: 1.5 | J41: 3.5 | K41: 16.5 | L41: 17 | M41: 0 | N41: 129 | O41: 122 | P41: 0.94573643 | Q41: 7.3939394 | R41: 0 | S41: 24.521175 | T41: 122 | V41: 0
...

Sheet Sheet1
A1: Line | B1: Experience | C1: Period | D1: Hiring Date | E1: Code | F1: Employee Name | G1: Target Visits (Experienced) | H1: Target Visits Done (Experienced) | I1: District Manager | J1: National Sales Manager | K1: Business Unit | L1: Area | M1: Calendar Days | N1: Holidays | O1: Leave Days | P1: Activity Days | Q1: NFA Days (Leave&Activity) | R1: Supposed Visit Days | S1: All Visit Days | T1: Missing Work Days | U1: Target Visits | V1: Target Visits Done | W1: Target Visits Achievement % | X1: Average Daily Visits (Actual Visit Days) | Y1: Calls per Visit | Z1: Average Visit Duration | AA1: Actual Visits | AB1: Daily Target Visits 2025 | AC1: Visits out of Target List
A3: Diab III | B3: =DATEDIF(D3,TODAY(),"M") -> 7 | C3: Non-Probation | D3: 12-Jul-2025 | E3: 1707 | F3: AbdelMoneim Sayed AbdelMoneim Sayed Darwish | G3: =U3 -> 173 | H3: =V3 -> 169 | I3: Peter AbdelNasser Fathy Habel | J3: Mahmoud Abdel Aziz El-Sayed Mohamed | K3: Kamal El-Din Magdy Abdel Fatah Allam | L3: DIAB-III ABBASEIA-KOBBAH | M3: 28 | N3: 0 | O3: 1 | P3: 2 | Q3: 3 | R3: 17 | S3: 18 | T3: 0 | U3: 173 | V3: 169 | W3: 0.97687861 | X3: 9.9411765 | Y3: 0 | Z3: 3.462426 | AA3: 169 | AC3: 0
A4: Diab III | B4: =DATEDIF(D4,TODAY(),"M") -> 20 | C4: Non-Probation | D4: 22-Jun-2024 | E4: 1188 | F4: Mahmoud Mohamed Abdelmahdy Abdullah | G4: =U4 -> 176 | H4: =V4 -> 155 | I4: Peter AbdelNasser Fathy Habel | J4: Mahmoud Abdel Aziz El-Sayed Mohamed | K4: Kamal El-Din Magdy Abdel Fatah Allam | L4: DIAB-III CAIRO EAST | M4: 28 | N4: 0 | O4: 3 | P4: 1.5 | Q4: 4.5 | R4: 15.5 | S4: 16 | T4: 0 | U4: 176 | V4: 155 | W4: 0.88068182 | X4: 10.387097 | Y4: 0.01242236 | Z4: 18.500725 | AA4: 161 | AC4: 6
A5: Diab III | B5: =DATEDIF(D5,TODAY(),"M") -> 15 | C5: Non-Probation | D5: 1-Dec-2024 | E5: 1331 | F5: Yasmin Sayed AbdelLatif Mohamed Hekal | G5: =U5 -> 161 | H5: =V5 -> 158 | I5: Peter AbdelNasser Fathy Habel | J5: Mahmoud Abdel Aziz El-Sayed Mohamed | K5: Kamal El-Din Magdy Abdel Fatah Allam | L5: DIAB-III AIN SHAMS | M5: 28 | N5: 0 | O5: 1 | P5: 1.5 | Q5: 2.5 | R5: 17.5 | S5: 18 | T5: 0 | U5: 161 | V5: 158 | W5: 0.98136646 | X5: 9.0285714 | Y5: 1.9050633 | Z5: 3.8904008 | AA5: 158 | AC5: 0
A6: Diab III | B6: =DATEDIF(D6,TODAY(),"M") -> 2 | C6: Probation | D6: 46025 | E6: 2008 | F6: Guirgis Samir Azmy Iskandar | G6: 0 | H6: 0 | I6: Peter AbdelNasser Fathy Habel | J6: Mahmoud Abdel Aziz El-Sayed Mohamed | K6: Kamal El-Din Magdy Abdel Fatah Allam | L6: DIAB-III HELIOPOLIS-A | M6: 28 | N6: 0 | O6: 3 | P6: 1 | Q6: 4 | R6: 16 | S6: 16 | T6: 0 | U6: 197 | V6: 123 | W6: 0.62436548 | X6: 8.375 | Y6: 0 | Z6: 3.6572139 | AA6: 134 | AC6: 11
A7: Diab III | B7: =DATEDIF(D7,TODAY(),"M") -> 18 | C7: Non-Probation | D7: 7-Sept-2024 | E7: 1268 | F7: Mariam Makram Ragheb Soliman | G7: =U7 -> 191 | H7: =V7 -> 154 | I7: Peter AbdelNasser Fathy Habel | J7: Mahmoud Abdel Aziz El-Sayed Mohamed | K7: Kamal El-Din Magdy Abdel Fatah Allam | L7: DIAB-III HELIOPOLIS-B | M7: 28 | N7: 0 | O7: 2 | P7: 2 | Q7: 4 | R7: 16 | S7: 17 | T7: 0 | U7: 191 | V7: 154 | W7: 0.80628272 | X7: 9.625 | Y7: 0 | Z7: 7.3560606 | AA7: 154 | AC7: 0
A8: Diab III | B8: =DATEDIF(D8,TODAY(),"M") -> 26 | C8: Non-Probation | D8: 1-Jan-2024 | E8: 1006 | F8: Kholoud El-Matarawy Mohamed Aly | G8: =U8 -> 177 | H8: =V8 -> 151 | I8: Peter AbdelNasser Fathy Habel | J8: Mahmoud Abdel Aziz El-Sayed Mohamed | K8: Kamal El-Din Magdy Abdel Fatah Allam | L8: DIAB-III NEW CAIRO | M8: 28 | N8: 0 | O8: 2 | P8: 1 | Q8: 3 | R8: 17 | S8: 17 | T8: 0 | U8: 177 | V8: 151 | W8: 0.85310734 | X8: 9.0588235 | Y8: 0 | Z8: 13.199784 | AA8: 154 | AC8: 3
A9: Diab III | B9: =DATEDIF(D9,TODAY(),"M") -> 1 | C9: Probation | D9: 46032 | E9: 2007 | F9: Rania Helmy Lotfy Mohamed ElAsour | G9: 0 | H9: 0 | I9: Peter AbdelNasser Fathy Habel | J9: Mahmoud Abdel Aziz El-Sayed Mohamed | K9: Kamal El-Din Magdy Abdel Fatah Allam | L9: DIAB-III ISMAILIA-SUIZ | M9: 28 | N9: 0 | O9: 2 | P9: 2 | Q9: 4 | R9: 16 | S9: 10 | T9: 6 | U9: 214 | V9: 66 | W9: 0.30841121 | X9: 4.125 | Y9: 0 | Z9: 3.3406566 | AA9: 66 | AC9: 0
A10: Diab III | B10: =DATEDIF(D10,TODAY(),"M") -> 4 | C10: Non-Probation | D10: 2-Nov-2025 | E10: 1839 | F10: Eman Hamdy Shahat Esmail | G10: =U10 -> 182 | H10: =V10 -> 144 | I10: Ahmed Adel Hosny Hassan | J10: Mahmoud Abdel Aziz El-Sayed Mohamed | K10: Kamal El-Din Magdy Abdel Fatah Allam | L10: DIAB-III CAIRO WEST | M10: 28 | N10: 0 | O10: 0 | P10: 1 | Q10: 1 | R10: 19 | S10: 17 | T10: 2 | U10: 182 | V10: 144 | W10: 0.79120879 | X10: 7.5789474 | Y10: 0 | Z10: 25.447106 | AA10: 144 | AC10: 0
A11: Diab III | B11: =DATEDIF(D11,TODAY(),"M") -> 2 | C11: Probation | D11: 46023 | E11: 2018 | F11: Mohamed Mostafa Mohamed Mahmoud Azzam | G11: 0 | H11: 0 | I11: Ahmed Adel Hosny Hassan | J11: Mahmoud Abdel Aziz El-Sayed Mohamed | K11: Kamal El-Din Magdy Abdel Fatah Allam | L11: DIAB-III CAIRO CENTER | M11: 28 | N11: 0 | O11: 1 | P11: 1.5 | Q11: 2.5 | R11: 17.5 | S11: 16 | T11: 1.5 | U11: 158 | V11: 120 | W11: 0.75949367 | X11: 6.8571429 | Y11: 0 | Z11: 12.007778 | AA11: 120 | AC11: 0
A12: Diab III | B12: =DATEDIF(D12,TODAY(),"M") -> 1 | C12: Probation | D12: 46032 | E12: 2074 | F12: Asmaa ElBel Zanaty Hussein Aly | G12: 0 | H12: 0 | I12: Ahmed Adel Hosny Hassan | J12: Mahmoud Abdel Aziz El-Sayed Mohamed | K12: Kamal El-Din Magdy Abdel Fatah Allam | L12: DIAB-III CAIRO SOUTH | M12: 28 | N12: 0 | O12: 0 | P12: 1 | Q12: 1 | R12: 19 | S12: 17 | T12: 2 | U12: 253 | V12: 131 | W12: 0.51778656 | X12: 6.8947368 | Y12: 0 | Z12: 16.027099 | AA12: 131 | AC12: 0
A13: Diab III | B13: =DATEDIF(D13,TODAY(),"M") -> 66 | C13: Non-Probation | D13: 29-Aug-2020 | E13: 230 | F13: Nourhan Ashraf Mostafa Hassan | G13: =U13 -> 147 | H13: =V13 -> 0 | I13: Ahmed Adel Hosny Hassan | J13: Mahmoud Abdel Aziz El-Sayed Mohamed | K13: Kamal El-Din Magdy Abdel Fatah Allam | L13: DIAB-III MAADI | M13: 28 | N13: 0 | O13: 0 | P13: 0 | Q13: 0 | R13: 20 | S13: 0 | T13: 20 | U13: 147 | V13: 0 | W13: 0 | X13: 0 | Y13: 0 | Z13: 0 | AA13: 0 | AC13: 0
A14: Diab III | B14: =DATEDIF(D14,TODAY(),"M") -> 26 | C14: Non-Probation | D14: 1-Jan-2024 | E14: 964 | F14: Fatma Fawzy Mohamed Mahmoud | G14: =U14 -> 189 | H14: =V14 -> 127 | I14: Ahmed Adel Hosny Hassan | J14: Mahmoud Abdel Aziz El-Sayed Mohamed | K14: Kamal El-Din Magdy Abdel Fatah Allam | L14: DIAB-III HELWAN | M14: 28 | N14: 0 | O14: 1 | P14: 1 | Q14: 2 | R14: 18 | S14: 15 | T14: 3 | U14: 189 | V14: 127 | W14: 0.67195767 | X14: 7.0555556 | Y14: 0.015748031 | Z14: 15.453018 | AA14: 127 | AC14: 0
A15: Diab III | B15: =DATEDIF(D15,TODAY(),"M") -> 1 | C15: Probation | D15: 46033 | E15: 2075 | F15: Maha Magdy AbdelSalam Mahmoud Farag | G15: 0 | H15: 0 | I15: Ahmed Adel Hosny Hassan | J15: Mahmoud Abdel Aziz El-Sayed Mohamed | K15: Kamal El-Din Magdy Abdel Fatah Allam | L15: DIAB-III QALUBIA-A | M15: 28 | N15: 0 | O15: 0 | P15: 1 | Q15: 1 | R15: 19 | S15: 16 | T15: 3 | U15: 197 | V15: 163 | W15: 0.82741117 | X15: 8.6315789 | Y15: 0.32317073 | Z15: 7.328252 | AA15: 164 | AC15: 1
A16: Diab III | B16: =DATEDIF(D16,TODAY(),"M") -> 2 | C16: Probation | D16: 46023 | E16: 2019 | F16: Mahmoud Lotfy Saied AbdelFatah | G16: 0 | H16: 0 | I16: Ahmed Adel Hosny Hassan | J16: Mahmoud Abdel Aziz El-Sayed Mohamed | K16: Kamal El-Din Magdy Abdel Fatah Allam | L16: DIAB-III QALUBIA-B | M16: 28 | N16: 0 | O16: 0 | P16: 0.5 | Q16: 0.5 | R16: 19.5 | S16: 14 | T16: 5.5 | U16: 194 | V16: 146 | W16: 0.75257732 | X16: 7.5384615 | Y16: 0.97278912 | Z16: 4.8744898 | AA16: 147 | AC16: 1
A17: Diab III | B17: =DATEDIF(D17,TODAY(),"M") -> 18 | C17: Non-Probation | D17: 10-Aug-2024 | E17: 1248 | F17: Mariam AbdelRahman Abdel Samie Abdel Wadod | G17: =U17 -> 216 | H17: =V17 -> 163 | I17: Vacant_Delta 1 | J17: Mahmoud Abdel Aziz El-Sayed Mohamed | K17: Kamal El-Din Magdy Abdel Fatah Allam | L17: DIAB-III SHARKIA-A | M17: 28 | N17: 0 | O17: 0 | P17: 0 | Q17: 0 | R17: 20 | S17: 17 | T17: 3 | U17: 216 | V17: 163 | W17: 0.75462963 | X17: 8.15 | Y17: 1.4969325 | Z17: 20.248466 | AA17: 163 | AC17: 0
A18: Diab III | B18: =DATEDIF(D18,TODAY(),"M") -> 2 | C18: Probation | D18: 46023 | E18: 2020 | F18: Youssef AbdelBaset Esmail Ahmed Ammar Badran | G18: 0 | H18: 0 | I18: Vacant_Delta 1 | J18: Mahmoud Abdel Aziz El-Sayed Mohamed | K18: Kamal El-Din Magdy Abdel Fatah Allam | L18: DIAB-III SHARKIA-B | M18: 28 | N18: 0 | O18: 0 | P18: 0 | Q18: 0 | R18: 20 | S18: 18 | T18: 2 | U18: 215 | V18: 148 | W18: 0.68837209 | X18: 7.8 | Y18: 1.2692308 | Z18: 17.218056 | AA18: 156 | AC18: 8
A19: Diab III | B19: =DATEDIF(D19,TODAY(),"M") -> 1 | C19: Probation | D19: 46032 | E19: 2039 | F19: Anas Mohamed ElSayed Ibrahim Salem | G19: 0 | H19: 0 | I19: Vacant_Delta 1 | J19: Mahmoud Abdel Aziz El-Sayed Mohamed | K19: Kamal El-Din Magdy Abdel Fatah Allam | L19: DIAB-III SHARKIA-C | M19: 28 | N19: 0 | O19: 0 | P19: 0 | Q19: 0 | R19: 20 | S19: 14 | T19: 6 | U19: 187 | V19: 110 | W19: 0.58823529 | X19: 6.55 | Y19: 1.9160305 | Z19: 5.3447837 | AA19: 131 | AC19: 21
A20: Diab III | B20: =DATEDIF(D20,TODAY(),"M") -> 26 | C20: Non-Probation | D20: 1-Jan-2024 | E20: 1047 | F20: Alaa Aly Aly Abu El-Enein | G20: =U20 -> 184 | H20: =V20 -> 157 | I20: Vacant_Delta 1 | J20: Mahmoud Abdel Aziz El-Sayed Mohamed | K20: Kamal El-Din Magdy Abdel Fatah Allam | L20: DIAB-III DAKAHLIA-A | M20: 28 | N20: 0 | O20: 0 | P20: 0 | Q20: 0 | R20: 20 | S20: 18 | T20: 2 | U20: 184 | V20: 157 | W20: 0.85326087 | X20: 7.9 | Y20: 0 | Z20: 15.115084 | AA20: 158 | AC20: 1
A21: Diab III | B21: =DATEDIF(D21,TODAY(),"M") -> 23 | C21: Non-Probation | D21: 14-Mar-2024 | E21: 1117 | F21: Reem Hassan Tolba Ibrahim | G21: =U21 -> 147 | H21: =V21 -> 123 | I21: Vacant_Delta 1 | J21: Mahmoud Abdel Aziz El-Sayed Mohamed | K21: Kamal El-Din Magdy Abdel Fatah Allam | L21: DIAB-III DAKAHLIA-B | M21: 28 | N21: 0 | O21: 0 | P21: 0 | Q21: 0 | R21: 20 | S21: 16 | T21: 4 | U21: 147 | V21: 123 | W21: 0.83673469 | X21: 6.15 | Y21: 1.8211382 | Z21: 25.008401 | AA21: 123 | AC21: 0
A22: Diab III | B22: =DATEDIF(D22,TODAY(),"M") -> 2 | C22: Probation | D22: 46023 | E22: 2021 | F22: Donia Mahmoud Mohamed Ahmed Mowafy | G22: 0 | H22: 0 | I22: Vacant_Delta 1 | J22: Mahmoud Abdel Aziz El-Sayed Mohamed | K22: Kamal El-Din Magdy Abdel Fatah Allam | L22: DIAB-III DAKAHLIA-C | M22: 28 | N22: 0 | O22: 0 | P22: 0 | Q22: 0 | R22: 20 | S22: 18 | T22: 2 | U22: 156 | V22: 169 | W22: 1.0833333 | X22: 8.45 | Y22: 1.7692308 | Z22: 5.2704142 | AA22: 169 | AC22: 0
A23: Diab III | B23: =DATEDIF(D23,TODAY(),"M") -> 67 | C23: Non-Probation | D23: 18-Jul-2020 | E23: 194 | F23: Menna Allah Hassouna Abbas Hassouna | G23: =U23 -> 232 | H23: =V23 -> 163 | I23: Vacant_Delta 1 | J23: Mahmoud Abdel Aziz El-Sayed Mohamed | K23: Kamal El-Din Magdy Abdel Fatah Allam | L23: DIAB-III DOMIAT | M23: 28 | N23: 0 | O23: 0 | P23: 0 | Q23: 0 | R23: 20 | S23: 17 | T23: 3 | U23: 232 | V23: 163 | W23: 0.70258621 | X23: 8.15 | Y23: 0 | Z23: 28.184969 | AA23: 163 | AC23: 0
A24: Diab III | B24: =DATEDIF(D24,TODAY(),"M") -> 26 | C24: Non-Probation | D24: 1-Jan-2024 | E24: 998 | F24: Shereen Tarek Gouda El-Sayed | G24: =U24 -> 212 | H24: =V24 -> 148 | I24: Vacant_Delta 1 | J24: Mahmoud Abdel Aziz El-Sayed Mohamed | K24: Kamal El-Din Magdy Abdel Fatah Allam | L24: DIAB-III P. SAID-N. SINAI | M24: 28 | N24: 0 | O24: 0 | P24: 0 | Q24: 0 | R24: 20 | S24: 17 | T24: 3 | U24: 212 | V24: 148 | W24: 0.69811321 | X24: 7.5 | Y24: 0 | Z24: 12.240222 | AA24: 150 | AC24: 2
A25: Diab III | B25: =DATEDIF(D25,TODAY(),"M") -> 2 | C25: Probation | D25: 46023 | E25: 1992 | F25: Mostafa Mahmoud Gaber ElHajjar | G25: 0 | H25: 0 | I25: Mohamed ElSayed Mostafa Gaber | J25: Mahmoud Abdel Aziz El-Sayed Mohamed | K25: Kamal El-Din Magdy Abdel Fatah Allam | L25: DIAB-III MENOFYA-A | M25: 28 | N25: 0 | O25: 0 | P25: 1 | Q25: 1 | R25: 19 | S25: 18 | T25: 1 | U25: 192 | V25: 141 | W25: 0.734375 | X25: 8.5263158 | Y25: 1.3641975 | Z25: 11.561214 | AA25: 162 | AC25: 21
A26: Diab III | B26: =DATEDIF(D26,TODAY(),"M") -> 2 | C26: Probation | D26: 46023 | E26: 1995 | F26: Zeinab Serry AbdelSamie Ammar | G26: 0 | H26: 0 | I26: Mohamed ElSayed Mostafa Gaber | J26: Mahmoud Abdel Aziz El-Sayed Mohamed | K26: Kamal El-Din Magdy Abdel Fatah Allam | L26: DIAB-III MENOFYA-B | M26: 28 | N26: 0 | O26: 1 | P26: 1 | Q26: 2 | R26: 18 | S26: 17 | T26: 1 | U26: 159 | V26: 137 | W26: 0.86163522 | X26: 8.6111111 | Y26: 0 | Z26: 12.290968 | AA26: 155 | AC26: 18
A27: Diab III | B27: =DATEDIF(D27,TODAY(),"M") -> 2 | C27: Probation | D27: 46023 | E27: 1994 | F27: Mariam AbuElMagd Ibrahim Abdullah ElNaggar | G27: 0 | H27: 0 | I27: Mohamed ElSayed Mostafa Gaber | J27: Mahmoud Abdel Aziz El-Sayed Mohamed | K27: Kamal El-Din Magdy Abdel Fatah Allam | L27: DIAB-III GHARBIA-B | M27: 28 | N27: 0 | O27: 2 | P27: 1 | Q27: 3 | R27: 17 | S27: 17 | T27: 0 | U27: 213 | V27: 132 | W27: 0.61971831 | X27: 8.1764706 | Y27: 1.0215827 | Z27: 7.2068345 | AA27: 139 | AC27: 7
A28: Diab III | B28: =DATEDIF(D28,TODAY(),"M") -> 2 | C28: Probation | D28: 46023 | E28: 1993 | F28: Mohamed Ahmed ElSayed Ahmed ElTaras | G28: 0 | H28: 0 | I28: Mohamed ElSayed Mostafa Gaber | J28: Mahmoud Abdel Aziz El-Sayed Mohamed | K28: Kamal El-Din Magdy Abdel Fatah Allam | L28: DIAB-III GHARBIA-A | M28: 28 | N28: 0 | O28: 1 | P28: 1 | Q28: 2 | R28: 18 | S28: 18 | T28: 0 | U28: 198 | V28: 92 | W28: 0.46464646 | X28: 7.8333333 | Y28: 0 | Z28: 5.1261229 | AA28: 141 | AC28: 49
A29: Diab III | B29: =DATEDIF(D29,TODAY(),"M") -> 1 | C29: Probation | D29: 46054 | E29: 2133 | F29: Hazem Mohamed HasaBallah Esmail Ibrahim | G29: 0 | H29: 0 | I29: Mohamed ElSayed Mostafa Gaber | J29: Mahmoud Abdel Aziz El-Sayed Mohamed | K29: Kamal El-Din Magdy Abdel Fatah Allam | L29: DIAB-III KAFR ELSHEIKH-A | M29: 28 | N29: 0 | O29: 0 | P29: 0 | Q29: 0 | R29: 20 | S29: 7 | T29: 13 | U29: 137 | V29: 35 | W29: 0.25547445 | X29: 2 | Y29: 0.5 | Z29: 8.8504167 | AA29: 40 | AC29: 5
A30: Diab III | B30: =DATEDIF(D30,TODAY(),"M") -> 28 | C30: Non-Probation | D30: 2-Nov-2023 | E30: 940 | F30: Mohamed Mohamed Mohamed Hassan Salah | G30: =U30 -> 224 | H30: =V30 -> 144 | I30: Mohamed ElSayed Mostafa Gaber | J30: Mahmoud Abdel Aziz El-Sayed Mohamed | K30: Kamal El-Din Magdy Abdel Fatah Allam | L30: DIAB-III KAFR ELSHEIKH-B | M30: 28 | N30: 0 | O30: 0 | P30: 1.5 | Q30: 1.5 | R30: 18.5 | S30: 18 | T30: 0.5 | U30: 224 | V30: 144 | W30: 0.64285714 | X30: 7.9459459 | Y30: 0 | Z30: 11.71746 | AA30: 147 | AC30: 3
A31: Diab III | B31: =DATEDIF(D31,TODAY(),"M") -> 1 | C31: Probation | D31: 46032 | E31: 2024 | F31: Ereny Awny Fouad Ibrahim Beshara | G31: 0 | H31: 0 | I31: Karim Mohamed Nagib Mohamed El-Demerdash | J31: Mahmoud Abdel Aziz El-Sayed Mohamed | K31: Kamal El-Din Magdy Abdel Fatah Allam | L31: DIAB-III ALEX EAST-A | M31: 28 | N31: 0 | O31: 1 | P31: 1.5 | Q31: 2.5 | R31: 17.5 | S31: 18 | T31: 0 | U31: 161 | V31: 161 | W31: 1 | X31: 9.3142857 | Y31: 0.97546012 | Z31: 10.494479 | AA31: 163 | AC31: 2
A32: Diab III | B32: =DATEDIF(D32,TODAY(),"M") -> 10 | C32: Non-Probation | D32: 12-Apr-2025 | E32: 1587 | F32: Rana Mohamed Gaber AbdelHamid | G32: =U32 -> 128 | H32: =V32 -> 128 | I32: Karim Mohamed Nagib Mohamed El-Demerdash | J32: Mahmoud Abdel Aziz El-Sayed Mohamed | K32: Kamal El-Din Magdy Abdel Fatah Allam | L32: DIAB-III ALEX EAST-B | M32: 28 | N32: 0 | O32: 1 | P32: 1.5 | Q32: 2.5 | R32: 17.5 | S32: 17 | T32: 0.5 | U32: 128 | V32: 128 | W32: 1 | X32: 7.3714286 | Y32: 1.0077519 | Z32: 17.777261 | AA32: 129 | AC32: 1
A33: Diab III | B33: =DATEDIF(D33,TODAY(),"M") -> 2 | C33: Probation | D33: 46023 | E33: 2023 | F33: Mohamed Hussein AbdelNaiem Ahmed AbdelNaiem | G33: 0 | H33: 0 | I33: Karim Mohamed Nagib Mohamed El-Demerdash | J33: Mahmoud Abdel Aziz El-Sayed Mohamed | K33: Kamal El-Din Magdy Abdel Fatah Allam | L33: DIAB-III ALEX WEST | M33: 28 | N33: 0 | O33: 1 | P33: 2 | Q33: 3 | R33: 17 | S33: 18 | T33: 0 | U33: 146 | V33: 119 | W33: 0.81506849 | X33: 7.0588235 | Y33: 1.9916667 | Z33: 3.8288889 | AA33: 120 | AC33: 1
A34: Diab III | B34: =DATEDIF(D34,TODAY(),"M") -> 6 | C34: Non-Probation | D34: 16-Aug-2025 | E34: 1757 | F34: Ingy Mahmoud Mohamed Ahmed ElSheikh | G34: =U34 -> 129 | H34: =V34 -> 122 | I34: Karim Mohamed Nagib Mohamed El-Demerdash | J34: Mahmoud Abdel Aziz El-Sayed Mohamed | K34: Kamal El-Din Magdy Abdel Fatah Allam | L34: DIAB-III ALEX CENTER-B | M34: 28 | N34: 0 | O34: 2 | P34: 1.5 | Q34: 3.5 | R34: 16.5 | S34: 17 | T34: 0 | U34: 129 | V34: 122 | W34: 0.94573643 | X34: 7.3939394 | Y34: 0 | Z34: 24.521175 | AA34: 122 | AC34: 0
A35: Diab III | B35: =DATEDIF(D35,TODAY(),"M") -> 26 | C35: Non-Probation | D35: 1-Jan-2024 | E35: 970 | F35: Marwa Mohamed Hussien Abdel Karim | G35: =U35 -> 135 | H35: =V35 -> 129 | I35: Karim Mohamed Nagib Mohamed El-Demerdash | J35: Mahmoud Abdel Aziz El-Sayed Mohamed | K35: Kamal El-Din Magdy Abdel Fatah Allam | L35: DIAB-II BEHIRA-A | M35: 28 | N35: 0 | O35: 2 | P35: 3.5 | Q35: 5.5 | R35: 14.5 | S35: 14 | T35: 0.5 | U35: 135 | V35: 129 | W35: 0.95555556 | X35: 8.8965517 | Y35: 0 | Z35: 37.73553 | AA35: 129 | AC35: 0
A36: Diab III | B36: =DATEDIF(D36,TODAY(),"M") -> 33 | C36: Non-Probation | D36: 20-May-2023 | E36: 788 | F36: Monica Ibrahim Guirgis Youssef | G36: =U36 -> 141 | H36: =V36 -> 121 | I36: Karim Mohamed Nagib Mohamed El-Demerdash | J36: Mahmoud Abdel Aziz El-Sayed Mohamed | K36: Kamal El-Din Magdy Abdel Fatah Allam | L36: DIAB-II BEHIRA-B | M36: 28 | N36: 0 | O36: 2 | P36: 1.5 | Q36: 3.5 | R36: 16.5 | S36: 17 | T36: 0 | U36: 141 | V36: 121 | W36: 0.85815603 | X36: 7.3333333 | Y36: 0.099173554 | Z36: 11.561983 | AA36: 121 | AC36: 0
A37: Diab III | B37: =DATEDIF(D37,TODAY(),"M") -> 1 | C37: Probation | D37: 46032 | E37: 2092 | F37: Mohamed Ayman Mohamed Mahmoud AbuShosha | G37: 0 | H37: 0 | I37: Karim Mohamed Nagib Mohamed El-Demerdash | J37: Mahmoud Abdel Aziz El-Sayed Mohamed | K37: Kamal El-Din Magdy Abdel Fatah Allam | L37: DIAB-II BEHIRA-C | M37: 28 | N37: 0 | O37: 0 | P37: 2.5 | Q37: 2.5 | R37: 17.5 | S37: 18 | T37: 0 | U37: 149 | V37: 144 | W37: 0.96644295 | X37: 8.8571429 | Y37: 1.9806452 | Z37: 7.7082796 | AA37: 155 | AC37: 11
A38: Diab III | B38: =DATEDIF(D38,TODAY(),"M") -> 33 | C38: Non-Probation | D38: 27-May-2023 | E38: 789 | F38: Kyrilles Latif Masoud Yassa | G38: =U38 -> 151 | H38: =V38 -> 126 | I38: Jacklyn Mamdouh Aziz Loka | J38: Mahmoud Abdel Aziz El-Sayed Mohamed | K38: Kamal El-Din Magdy Abdel Fatah Allam | L38: DIAB-III HARAM-GIZA CENTERS | M38: 28 | N38: 0 | O38: 2 | P38: 0 | Q38: 2 | R38: 18 | S38: 17 | T38: 1 | U38: 151 | V38: 126 | W38: 0.83443709 | X38: 7.2777778 | Y38: 1.9312977 | Z38: 13.690076 | AA38: 131 | AC38: 5
A39: Diab III | B39: =DATEDIF(D39,TODAY(),"M") -> 24 | C39: Non-Probation | D39: 2-Mar-2024 | E39: 1114 | F39: Mostafa Khaled Mohamed Mohamed | G39: =U39 -> 156 | H39: =V39 -> 140 | I39: Jacklyn Mamdouh Aziz Loka | J39: Mahmoud Abdel Aziz El-Sayed Mohamed | K39: Kamal El-Din Magdy Abdel Fatah Allam | L39: DIAB-III MOHANDSEEN | M39: 28 | N39: 0 | O39: 1 | P39: 0 | Q39: 1 | R39: 19 | S39: 16 | T39: 3 | U39: 156 | V39: 140 | W39: 0.8974359 | X39: 7.5789474 | Y39: 0 | Z39: 7.4291667 | AA39: 144 | AC39: 4
A40: Diab III | B40: =DATEDIF(D40,TODAY(),"M") -> 0 | C40: Probation | D40: 46066 | E40: 2132 | F40: Amin Ibrahim Mohamed Amin | G40: 0 | H40: 0 | I40: Jacklyn Mamdouh Aziz Loka | J40: Mahmoud Abdel Aziz El-Sayed Mohamed | K40: Kamal El-Din Magdy Abdel Fatah Allam | L40: DIAB-III FAISAL | M40: 28 | N40: 0 | O40: 0 | P40: 0 | Q40: 0 | R40: 20 | S40: 1 | T40: 19 | U40: 168 | V40: 5 | W40: 0.029761905 | X40: 0.3 | Y40: 0.33333333 | Z40: 3.6527778 | AA40: 6 | AC40: 1
A41: Diab III | B41: =DATEDIF(D41,TODAY(),"M") -> 2 | C41: Probation | D41: 46023 | E41: 2009 | F41: Kamar AbdelSamie AbdelWahed Sawy | G41: 0 | H41: 0 | I41: Vacant_Upper Egypt B | J41: Mahmoud Abdel Aziz El-Sayed Mohamed | K41: Kamal El-Din Magdy Abdel Fatah Allam | L41: DIAB-III MENIA-A | M41: 28 | N41: 0 | O41: 1 | P41: 1.5 | Q41: 2.5 | R41: 17.5 | S41: 18 | T41: 0 | U41: 213 | V41: 164 | W41: 0.76995305 | X41: 9.3714286 | Y41: 1.9329268 | Z41: 5.3382114 | AA41: 164 | AC41: 0
...

Sheet sheet
A1: Line | B1: Hiring Date | C1: Code | D1: Name | E1: Area | F1: Calendar Days | G1: Holidays | H1: Leave Days | I1: Activity Days | J1: NFA Days (Leave&Activity) | K1: Supposed Visit Days | L1: All Visit Days | M1: Missing Work Days | N1: Target Visits | O1: Target Visits Done | P1: Target Visits Achievement % | Q1: Average Daily Visits (Actual Visit Days) | R1: Calls per Visit | S1: Average Visit Duration | T1: Actual Visits | U1: Daily Target Visits 2025 | V1: Visits out of Target List
A3: Diab III | B3: 12-Jul-2025 | C3: 1707 | D3: AbdelMoneim Sayed AbdelMoneim Sayed Darwish | E3: DIAB-III ABBASEIA-KOBBAH | F3: =VLOOKUP(D3,Performance!A:B,2,0) -> 28 | G3: =VLOOKUP(D3,Performance!A:C,3,0) -> 0 | H3: =VLOOKUP(D3,Performance!A:D,4,0) -> 1 | I3: =VLOOKUP(D3,Performance!A:E,5,0) -> 2 | J3: =VLOOKUP(D3,Performance!A:F,6,0) -> 3 | K3: =VLOOKUP(D3,Performance!A:G,7,0) -> 17 | L3: =VLOOKUP(D3,Performance!A:I,9,0) -> 18 | M3: =VLOOKUP(D3,Performance!A:H,8,0) -> 0 | N3: =VLOOKUP(D3,Performance!A:J,10,0) -> 173 | O3: =VLOOKUP(D3,Performance!A:K,11,0) -> 169 | P3: =VLOOKUP(D3,Performance!A:L,12,0) -> 0.97687861 | Q3: =VLOOKUP(D3,Performance!A:M,13,0) -> 9.9411765 | R3: =VLOOKUP(D3,Performance!A:N,14,0) -> 0 | S3: =VLOOKUP(D3,Performance!A:O,15,0) -> 3.462426 | T3: =VLOOKUP(D3,performance1,16,0) -> 169 | V3: =T3-O3 -> 0
A4: Diab III | B4: 22-Jun-2024 | C4: 1188 | D4: Mahmoud Mohamed Abdelmahdy Abdullah | E4: DIAB-III CAIRO EAST | F4: =VLOOKUP(D4,Performance!A:B,2,0) -> 28 | G4: =VLOOKUP(D4,Performance!A:C,3,0) -> 0 | H4: =VLOOKUP(D4,Performance!A:D,4,0) -> 3 | I4: =VLOOKUP(D4,Performance!A:E,5,0) -> 1.5 | J4: =VLOOKUP(D4,Performance!A:F,6,0) -> 4.5 | K4: =VLOOKUP(D4,Performance!A:G,7,0) -> 15.5 | L4: =VLOOKUP(D4,Performance!A:I,9,0) -> 16 | M4: =VLOOKUP(D4,Performance!A:H,8,0) -> 0 | N4: =VLOOKUP(D4,Performance!A:J,10,0) -> 176 | O4: =VLOOKUP(D4,Performance!A:K,11,0) -> 155 | P4: =VLOOKUP(D4,Performance!A:L,12,0) -> 0.88068182 | Q4: =VLOOKUP(D4,Performance!A:M,13,0) -> 10.387097 | R4: =VLOOKUP(D4,Performance!A:N,14,0) -> 0.01242236 | S4: =VLOOKUP(D4,Performance!A:O,15,0) -> 18.500725 | T4: =VLOOKUP(D4,performance1,16,0) -> 161 | V4: =T4-O4 -> 6
A5: Diab III | B5: 1-Dec-2024 | C5: 1331 | D5: Yasmin Sayed AbdelLatif Mohamed Hekal | E5: DIAB-III AIN SHAMS | F5: =VLOOKUP(D5,Performance!A:B,2,0) -> 28 | G5: =VLOOKUP(D5,Performance!A:C,3,0) -> 0 | H5: =VLOOKUP(D5,Performance!A:D,4,0) -> 1 | I5: =VLOOKUP(D5,Performance!A:E,5,0) -> 1.5 | J5: =VLOOKUP(D5,Performance!A:F,6,0) -> 2.5 | K5: =VLOOKUP(D5,Performance!A:G,7,0) -> 17.5 | L5: =VLOOKUP(D5,Performance!A:I,9,0) -> 18 | M5: =VLOOKUP(D5,Performance!A:H,8,0) -> 0 | N5: =VLOOKUP(D5,Performance!A:J,10,0) -> 161 | O5: =VLOOKUP(D5,Performance!A:K,11,0) -> 158 | P5: =VLOOKUP(D5,Performance!A:L,12,0) -> 0.98136646 | Q5: =VLOOKUP(D5,Performance!A:M,13,0) -> 9.0285714 | R5: =VLOOKUP(D5,Performance!A:N,14,0) -> 1.9050633 | S5: =VLOOKUP(D5,Performance!A:O,15,0) -> 3.8904008 | T5: =VLOOKUP(D5,performance1,16,0) -> 158 | V5: =T5-O5 -> 0
A6: Diab III | B6: 46025 | C6: 2008 | D6: Guirgis Samir Azmy Iskandar | E6: DIAB-III HELIOPOLIS-A | F6: =VLOOKUP(D6,Performance!A:B,2,0) -> 28 | G6: =VLOOKUP(D6,Performance!A:C,3,0) -> 0 | H6: =VLOOKUP(D6,Performance!A:D,4,0) -> 3 | I6: =VLOOKUP(D6,Performance!A:E,5,0) -> 1 | J6: =VLOOKUP(D6,Performance!A:F,6,0) -> 4 | K6: =VLOOKUP(D6,Performance!A:G,7,0) -> 16 | L6: =VLOOKUP(D6,Performance!A:I,9,0) -> 16 | M6: =VLOOKUP(D6,Performance!A:H,8,0) -> 0 | N6: =VLOOKUP(D6,Performance!A:J,10,0) -> 197 | O6: =VLOOKUP(D6,Performance!A:K,11,0) -> 123 | P6: =VLOOKUP(D6,Performance!A:L,12,0) -> 0.62436548 | Q6: =VLOOKUP(D6,Performance!A:M,13,0) -> 8.375 | R6: =VLOOKUP(D6,Performance!A:N,14,0) -> 0 | S6: =VLOOKUP(D6,Performance!A:O,15,0) -> 3.6572139 | T6: =VLOOKUP(D6,performance1,16,0) -> 134 | V6: =T6-O6 -> 11
A7: Diab III | B7: 7-Sept-2024 | C7: 1268 | D7: Mariam Makram Ragheb Soliman | E7: DIAB-III HELIOPOLIS-B | F7: =VLOOKUP(D7,Performance!A:B,2,0) -> 28 | G7: =VLOOKUP(D7,Performance!A:C,3,0) -> 0 | H7: =VLOOKUP(D7,Performance!A:D,4,0) -> 2 | I7: =VLOOKUP(D7,Performance!A:E,5,0) -> 2 | J7: =VLOOKUP(D7,Performance!A:F,6,0) -> 4 | K7: =VLOOKUP(D7,Performance!A:G,7,0) -> 16 | L7: =VLOOKUP(D7,Performance!A:I,9,0) -> 17 | M7: =VLOOKUP(D7,Performance!A:H,8,0) -> 0 | N7: =VLOOKUP(D7,Performance!A:J,10,0) -> 191 | O7: =VLOOKUP(D7,Performance!A:K,11,0) -> 154 | P7: =VLOOKUP(D7,Performance!A:L,12,0) -> 0.80628272 | Q7: =VLOOKUP(D7,Performance!A:M,13,0) -> 9.625 | R7: =VLOOKUP(D7,Performance!A:N,14,0) -> 0 | S7: =VLOOKUP(D7,Performance!A:O,15,0) -> 7.3560606 | T7: =VLOOKUP(D7,performance1,16,0) -> 154 | V7: =T7-O7 -> 0
A8: Diab III | D8: Vacant_NasrCity | E8: DIAB-III NASR CITY | F8: =VLOOKUP(D8,Performance!A:B,2,0) -> #N/A | G8: =VLOOKUP(D8,Performance!A:C,3,0) -> #N/A | H8: =VLOOKUP(D8,Performance!A:D,4,0) -> #N/A | I8: =VLOOKUP(D8,Performance!A:E,5,0) -> #N/A | J8: =VLOOKUP(D8,Performance!A:F,6,0) -> #N/A | K8: =VLOOKUP(D8,Performance!A:G,7,0) -> #N/A | L8: =VLOOKUP(D8,Performance!A:I,9,0) -> #N/A | M8: =VLOOKUP(D8,Performance!A:H,8,0) -> #N/A | N8: =VLOOKUP(D8,Performance!A:J,10,0) -> #N/A | O8: =VLOOKUP(D8,Performance!A:K,11,0) -> #N/A | P8: =VLOOKUP(D8,Performance!A:L,12,0) -> #N/A | Q8: =VLOOKUP(D8,Performance!A:M,13,0) -> #N/A | R8: =VLOOKUP(D8,Performance!A:N,14,0) -> #N/A | S8: =VLOOKUP(D8,Performance!A:O,15,0) -> #N/A | T8: =VLOOKUP(D8,performance1,16,0) -> #N/A | V8: =T8-O8 -> #N/A
A9: Diab III | B9: 1-Jan-2024 | C9: 1006 | D9: Kholoud El-Matarawy Mohamed Aly | E9: DIAB-III NEW CAIRO | F9: =VLOOKUP(D9,Performance!A:B,2,0) -> 28 | G9: =VLOOKUP(D9,Performance!A:C,3,0) -> 0 | H9: =VLOOKUP(D9,Performance!A:D,4,0) -> 2 | I9: =VLOOKUP(D9,Performance!A:E,5,0) -> 1 | J9: =VLOOKUP(D9,Performance!A:F,6,0) -> 3 | K9: =VLOOKUP(D9,Performance!A:G,7,0) -> 17 | L9: =VLOOKUP(D9,Performance!A:I,9,0) -> 17 | M9: =VLOOKUP(D9,Performance!A:H,8,0) -> 0 | N9: =VLOOKUP(D9,Performance!A:J,10,0) -> 177 | O9: =VLOOKUP(D9,Performance!A:K,11,0) -> 151 | P9: =VLOOKUP(D9,Performance!A:L,12,0) -> 0.85310734 | Q9: =VLOOKUP(D9,Performance!A:M,13,0) -> 9.0588235 | R9: =VLOOKUP(D9,Performance!A:N,14,0) -> 0 | S9: =VLOOKUP(D9,Performance!A:O,15,0) -> 13.199784 | T9: =VLOOKUP(D9,performance1,16,0) -> 154 | V9: =T9-O9 -> 3
A10: Diab III | B10: 46032 | C10: 2007 | D10: Rania Helmy Lotfy Mohamed ElAsour | E10: DIAB-III ISMAILIA-SUIZ | F10: =VLOOKUP(D10,Performance!A:B,2,0) -> 28 | G10: =VLOOKUP(D10,Performance!A:C,3,0) -> 0 | H10: =VLOOKUP(D10,Performance!A:D,4,0) -> 2 | I10: =VLOOKUP(D10,Performance!A:E,5,0) -> 2 | J10: =VLOOKUP(D10,Performance!A:F,6,0) -> 4 | K10: =VLOOKUP(D10,Performance!A:G,7,0) -> 16 | L10: =VLOOKUP(D10,Performance!A:I,9,0) -> 10 | M10: =VLOOKUP(D10,Performance!A:H,8,0) -> 6 | N10: =VLOOKUP(D10,Performance!A:J,10,0) -> 214 | O10: =VLOOKUP(D10,Performance!A:K,11,0) -> 66 | P10: =VLOOKUP(D10,Performance!A:L,12,0) -> 0.30841121 | Q10: =VLOOKUP(D10,Performance!A:M,13,0) -> 4.125 | R10: =VLOOKUP(D10,Performance!A:N,14,0) -> 0 | S10: =VLOOKUP(D10,Performance!A:O,15,0) -> 3.3406566 | T10: =VLOOKUP(D10,performance1,16,0) -> 66 | V10: =T10-O10 -> 0
A11: Diab III | B11: 1-Feb-2025 | C11: 1439 | D11: Peter AbdelNasser Fathy Habel | E11: DIAB-III DM CAIRO B | F11: =VLOOKUP(D11,Performance!A:B,2,0) -> 28 | G11: =VLOOKUP(D11,Performance!A:C,3,0) -> 0 | H11: =VLOOKUP(D11,Performance!A:D,4,0) -> 0 | I11: =VLOOKUP(D11,Performance!A:E,5,0) -> 0 | J11: =VLOOKUP(D11,Performance!A:F,6,0) -> 0 | K11: =VLOOKUP(D11,Performance!A:G,7,0) -> 20 | L11: =VLOOKUP(D11,Performance!A:I,9,0) -> 15 | M11: =VLOOKUP(D11,Performance!A:H,8,0) -> 5 | N11: =SUM(N3:N5,N7,N9) -> 878 | O11: =SUM(O3:O5,O7,O9) -> 787 | P11: =O11/N11 -> 0.89635535 | Q11: =AVERAGE(Q3:Q5,Q7,Q9) -> 9.6081336 | R11: =AVERAGE(R3:R5,R7,R9) -> 0.38349713 | S11: =AVERAGE(S3:S5,S7,S9) -> 9.2818791 | T11: =VLOOKUP(D11,performance1,16,0) -> 36
A12: Diab III | D12: Vacant_Shoubraelkhemah | E12: DIAB-III SHOBRA EL KHEMAH | F12: =VLOOKUP(D12,Performance!A:B,2,0) -> #N/A | G12: =VLOOKUP(D12,Performance!A:C,3,0) -> #N/A | H12: =VLOOKUP(D12,Performance!A:D,4,0) -> #N/A | I12: =VLOOKUP(D12,Performance!A:E,5,0) -> #N/A | J12: =VLOOKUP(D12,Performance!A:F,6,0) -> #N/A | K12: =VLOOKUP(D12,Performance!A:G,7,0) -> #N/A | L12: =VLOOKUP(D12,Performance!A:I,9,0) -> #N/A | M12: =VLOOKUP(D12,Performance!A:H,8,0) -> #N/A | N12: =VLOOKUP(D12,Performance!A:J,10,0) -> #N/A | O12: =VLOOKUP(D12,Performance!A:K,11,0) -> #N/A | P12: =VLOOKUP(D12,Performance!A:L,12,0) -> #N/A | Q12: =VLOOKUP(D12,Performance!A:M,13,0) -> #N/A | R12: =VLOOKUP(D12,Performance!A:N,14,0) -> #N/A | S12: =VLOOKUP(D12,Performance!A:O,15,0) -> #N/A | T12: =VLOOKUP(D12,performance1,16,0) -> #N/A | V12: =T12-O12 -> #N/A
A13: Diab III | B13: 2-Nov-2025 | C13: 1839 | D13: Eman Hamdy Shahat Esmail | E13: DIAB-III CAIRO WEST | F13: =VLOOKUP(D13,Performance!A:B,2,0) -> 28 | G13: =VLOOKUP(D13,Performance!A:C,3,0) -> 0 | H13: =VLOOKUP(D13,Performance!A:D,4,0) -> 0 | I13: =VLOOKUP(D13,Performance!A:E,5,0) -> 1 | J13: =VLOOKUP(D13,Performance!A:F,6,0) -> 1 | K13: =VLOOKUP(D13,Performance!A:G,7,0) -> 19 | L13: =VLOOKUP(D13,Performance!A:I,9,0) -> 17 | M13: =VLOOKUP(D13,Performance!A:H,8,0) -> 2 | N13: =VLOOKUP(D13,Performance!A:J,10,0) -> 182 | O13: =VLOOKUP(D13,Performance!A:K,11,0) -> 144 | P13: =VLOOKUP(D13,Performance!A:L,12,0) -> 0.79120879 | Q13: =VLOOKUP(D13,Performance!A:M,13,0) -> 7.5789474 | R13: =VLOOKUP(D13,Performance!A:N,14,0) -> 0 | S13: =VLOOKUP(D13,Performance!A:O,15,0) -> 25.447106 | T13: =VLOOKUP(D13,performance1,16,0) -> 144 | V13: =T13-O13 -> 0
A14: Diab III | B14: 46023 | C14: 2018 | D14: Mohamed Mostafa Mohamed Mahmoud Azzam | E14: DIAB-III CAIRO CENTER | F14: =VLOOKUP(D14,Performance!A:B,2,0) -> 28 | G14: =VLOOKUP(D14,Performance!A:C,3,0) -> 0 | H14: =VLOOKUP(D14,Performance!A:D,4,0) -> 1 | I14: =VLOOKUP(D14,Performance!A:E,5,0) -> 1.5 | J14: =VLOOKUP(D14,Performance!A:F,6,0) -> 2.5 | K14: =VLOOKUP(D14,Performance!A:G,7,0) -> 17.5 | L14: =VLOOKUP(D14,Performance!A:I,9,0) -> 16 | M14: =VLOOKUP(D14,Performance!A:H,8,0) -> 1.5 | N14: =VLOOKUP(D14,Performance!A:J,10,0) -> 158 | O14: =VLOOKUP(D14,Performance!A:K,11,0) -> 120 | P14: =VLOOKUP(D14,Performance!A:L,12,0) -> 0.75949367 | Q14: =VLOOKUP(D14,Performance!A:M,13,0) -> 6.8571429 | R14: =VLOOKUP(D14,Performance!A:N,14,0) -> 0 | S14: =VLOOKUP(D14,Performance!A:O,15,0) -> 12.007778 | T14: =VLOOKUP(D14,performance1,16,0) -> 120 | V14: =T14-O14 -> 0
A15: Diab III | B15: 46032 | C15: 2074 | D15: Asmaa ElBel Zanaty Hussein Aly | E15: DIAB-III CAIRO SOUTH | F15: =VLOOKUP(D15,Performance!A:B,2,0) -> 28 | G15: =VLOOKUP(D15,Performance!A:C,3,0) -> 0 | H15: =VLOOKUP(D15,Performance!A:D,4,0) -> 0 | I15: =VLOOKUP(D15,Performance!A:E,5,0) -> 1 | J15: =VLOOKUP(D15,Performance!A:F,6,0) -> 1 | K15: =VLOOKUP(D15,Performance!A:G,7,0) -> 19 | L15: =VLOOKUP(D15,Performance!A:I,9,0) -> 17 | M15: =VLOOKUP(D15,Performance!A:H,8,0) -> 2 | N15: =VLOOKUP(D15,Performance!A:J,10,0) -> 253 | O15: =VLOOKUP(D15,Performance!A:K,11,0) -> 131 | P15: =VLOOKUP(D15,Performance!A:L,12,0) -> 0.51778656 | Q15: =VLOOKUP(D15,Performance!A:M,13,0) -> 6.8947368 | R15: =VLOOKUP(D15,Performance!A:N,14,0) -> 0 | S15: =VLOOKUP(D15,Performance!A:O,15,0) -> 16.027099 | T15: =VLOOKUP(D15,performance1,16,0) -> 131 | V15: =T15-O15 -> 0
A16: Diab III | B16: 29-Aug-2020 | C16: 230 | D16: Nourhan Ashraf Mostafa Hassan | E16: DIAB-III MAADI | F16: =VLOOKUP(D16,Performance!A:B,2,0) -> 28 | G16: =VLOOKUP(D16,Performance!A:C,3,0) -> 0 | H16: =VLOOKUP(D16,Performance!A:D,4,0) -> 0 | I16: =VLOOKUP(D16,Performance!A:E,5,0) -> 0 | J16: =VLOOKUP(D16,Performance!A:F,6,0) -> 0 | K16: =VLOOKUP(D16,Performance!A:G,7,0) -> 20 | L16: =VLOOKUP(D16,Performance!A:I,9,0) -> 0 | M16: =VLOOKUP(D16,Performance!A:H,8,0) -> 20 | N16: =VLOOKUP(D16,Performance!A:J,10,0) -> 147 | O16: =VLOOKUP(D16,Performance!A:K,11,0) -> 0 | P16: =VLOOKUP(D16,Performance!A:L,12,0) -> 0 | Q16: =VLOOKUP(D16,Performance!A:M,13,0) -> 0 | R16: =VLOOKUP(D16,Performance!A:N,14,0) -> 0 | S16: =VLOOKUP(D16,Performance!A:O,15,0) -> 0 | T16: =VLOOKUP(D16,performance1,16,0) -> 0 | V16: =T16-O16 -> 0
A17: Diab III | B17: 1-Jan-2024 | C17: 964 | D17: Fatma Fawzy Mohamed Mahmoud | E17: DIAB-III HELWAN | F17: =VLOOKUP(D17,Performance!A:B,2,0) -> 28 | G17: =VLOOKUP(D17,Performance!A:C,3,0) -> 0 | H17: =VLOOKUP(D17,Performance!A:D,4,0) -> 1 | I17: =VLOOKUP(D17,Performance!A:E,5,0) -> 1 | J17: =VLOOKUP(D17,Performance!A:F,6,0) -> 2 | K17: =VLOOKUP(D17,Performance!A:G,7,0) -> 18 | L17: =VLOOKUP(D17,Performance!A:I,9,0) -> 15 | M17: =VLOOKUP(D17,Performance!A:H,8,0) -> 3 | N17: =VLOOKUP(D17,Performance!A:J,10,0) -> 189 | O17: =VLOOKUP(D17,Performance!A:K,11,0) -> 127 | P17: =VLOOKUP(D17,Performance!A:L,12,0) -> 0.67195767 | Q17: =VLOOKUP(D17,Performance!A:M,13,0) -> 7.0555556 | R17: =VLOOKUP(D17,Performance!A:N,14,0) -> 0.015748031 | S17: =VLOOKUP(D17,Performance!A:O,15,0) -> 15.453018 | T17: =VLOOKUP(D17,performance1,16,0) -> 127 | V17: =T17-O17 -> 0
A18: Diab III | B18: 46033 | C18: 2075 | D18: Maha Magdy AbdelSalam Mahmoud Farag | E18: DIAB-III QALUBIA-A | F18: =VLOOKUP(D18,Performance!A:B,2,0) -> 28 | G18: =VLOOKUP(D18,Performance!A:C,3,0) -> 0 | H18: =VLOOKUP(D18,Performance!A:D,4,0) -> 0 | I18: =VLOOKUP(D18,Performance!A:E,5,0) -> 1 | J18: =VLOOKUP(D18,Performance!A:F,6,0) -> 1 | K18: =VLOOKUP(D18,Performance!A:G,7,0) -> 19 | L18: =VLOOKUP(D18,Performance!A:I,9,0) -> 16 | M18: =VLOOKUP(D18,Performance!A:H,8,0) -> 3 | N18: =VLOOKUP(D18,Performance!A:J,10,0) -> 197 | O18: =VLOOKUP(D18,Performance!A:K,11,0) -> 163 | P18: =VLOOKUP(D18,Performance!A:L,12,0) -> 0.82741117 | Q18: =VLOOKUP(D18,Performance!A:M,13,0) -> 8.6315789 | R18: =VLOOKUP(D18,Performance!A:N,14,0) -> 0.32317073 | S18: =VLOOKUP(D18,Performance!A:O,15,0) -> 7.328252 | T18: =VLOOKUP(D18,performance1,16,0) -> 164 | V18: =T18-O18 -> 1
A19: Diab III | B19: 46023 | C19: 2019 | D19: Mahmoud Lotfy Saied AbdelFatah | E19: DIAB-III QALUBIA-B | F19: =VLOOKUP(D19,Performance!A:B,2,0) -> 28 | G19: =VLOOKUP(D19,Performance!A:C,3,0) -> 0 | H19: =VLOOKUP(D19,Performance!A:D,4,0) -> 0 | I19: =VLOOKUP(D19,Performance!A:E,5,0) -> 0.5 | J19: =VLOOKUP(D19,Performance!A:F,6,0) -> 0.5 | K19: =VLOOKUP(D19,Performance!A:G,7,0) -> 19.5 | L19: =VLOOKUP(D19,Performance!A:I,9,0) -> 14 | M19: =VLOOKUP(D19,Performance!A:H,8,0) -> 5.5 | N19: =VLOOKUP(D19,Performance!A:J,10,0) -> 194 | O19: =VLOOKUP(D19,Performance!A:K,11,0) -> 146 | P19: =VLOOKUP(D19,Performance!A:L,12,0) -> 0.75257732 | Q19: =VLOOKUP(D19,Performance!A:M,13,0) -> 7.5384615 | R19: =VLOOKUP(D19,Performance!A:N,14,0) -> 0.97278912 | S19: =VLOOKUP(D19,Performance!A:O,15,0) -> 4.8744898 | T19: =VLOOKUP(D19,performance1,16,0) -> 147 | V19: =T19-O19 -> 1
A20: Diab III | B20: 46023 | C20: 1902 | D20: Ahmed Adel Hosny Hassan | E20: DIAB-III DM CAIRO A | F20: =VLOOKUP(D20,Performance!A:B,2,0) -> 28 | G20: =VLOOKUP(D20,Performance!A:C,3,0) -> 0 | H20: =VLOOKUP(D20,Performance!A:D,4,0) -> 0 | I20: =VLOOKUP(D20,Performance!A:E,5,0) -> 0 | J20: =VLOOKUP(D20,Performance!A:F,6,0) -> 0 | K20: =VLOOKUP(D20,Performance!A:G,7,0) -> 20 | L20: =VLOOKUP(D20,Performance!A:I,9,0) -> 13 | M20: =VLOOKUP(D20,Performance!A:H,8,0) -> 7 | N20: =SUM(N13,N16:N17) -> 518 | O20: =SUM(O13,O16:O17) -> 271 | P20: =O20/N20 -> 0.52316602 | Q20: =AVERAGE(Q13,Q16:Q17) -> 4.8781676 | R20: =AVERAGE(R13,R16:R17) -> 0.0052493438 | S20: =AVERAGE(S13,S16:S17) -> 13.633375 | T20: =SUM(T13,T16:T17) -> 271
A21: Diab III | B21: 10-Aug-2024 | C21: 1248 | D21: Mariam AbdelRahman Abdel Samie Abdel Wadod | E21: DIAB-III SHARKIA-A | F21: =VLOOKUP(D21,Performance!A:B,2,0) -> 28 | G21: =VLOOKUP(D21,Performance!A:C,3,0) -> 0 | H21: =VLOOKUP(D21,Performance!A:D,4,0) -> 0 | I21: =VLOOKUP(D21,Performance!A:E,5,0) -> 0 | J21: =VLOOKUP(D21,Performance!A:F,6,0) -> 0 | K21: =VLOOKUP(D21,Performance!A:G,7,0) -> 20 | L21: =VLOOKUP(D21,Performance!A:I,9,0) -> 17 | M21: =VLOOKUP(D21,Performance!A:H,8,0) -> 3 | N21: =VLOOKUP(D21,Performance!A:J,10,0) -> 216 | O21: =VLOOKUP(D21,Performance!A:K,11,0) -> 163 | P21: =VLOOKUP(D21,Performance!A:L,12,0) -> 0.75462963 | Q21: =VLOOKUP(D21,Performance!A:M,13,0) -> 8.15 | R21: =VLOOKUP(D21,Performance!A:N,14,0) -> 1.4969325 | S21: =VLOOKUP(D21,Performance!A:O,15,0) -> 20.248466 | T21: =VLOOKUP(D21,performance1,16,0) -> 163 | V21: =T21-O21 -> 0
A22: Diab III | B22: 46023 | C22: 2020 | D22: Youssef AbdelBaset Esmail Ahmed Ammar Badran | E22: DIAB-III SHARKIA-B | F22: =VLOOKUP(D22,Performance!A:B,2,0) -> 28 | G22: =VLOOKUP(D22,Performance!A:C,3,0) -> 0 | H22: =VLOOKUP(D22,Performance!A:D,4,0) -> 0 | I22: =VLOOKUP(D22,Performance!A:E,5,0) -> 0 | J22: =VLOOKUP(D22,Performance!A:F,6,0) -> 0 | K22: =VLOOKUP(D22,Performance!A:G,7,0) -> 20 | L22: =VLOOKUP(D22,Performance!A:I,9,0) -> 18 | M22: =VLOOKUP(D22,Performance!A:H,8,0) -> 2 | N22: =VLOOKUP(D22,Performance!A:J,10,0) -> 215 | O22: =VLOOKUP(D22,Performance!A:K,11,0) -> 148 | P22: =VLOOKUP(D22,Performance!A:L,12,0) -> 0.68837209 | Q22: =VLOOKUP(D22,Performance!A:M,13,0) -> 7.8 | R22: =VLOOKUP(D22,Performance!A:N,14,0) -> 1.2692308 | S22: =VLOOKUP(D22,Performance!A:O,15,0) -> 17.218056 | T22: =VLOOKUP(D22,performance1,16,0) -> 156 | V22: =T22-O22 -> 8
